testLog     :INFO     xi
2015-10-05 15:12:51,577-test.py:27-testLog-xi
2015-10-05 15:17:53,070-test.py:20-testLog-执行测试脚本包括 ['judgeFinish.py', 'LoginPage.py', 'manTest.py', 'message.py', 'newProject.py', 'PageCommonContent.py', 'peocessThirty.py', 'process.py', 'processFive.py', 'processOne.py', 'processSeventeen.py', 'processSix.py', 'processThirteen.py', 'processThree.py', 'processTwelve.py', 'processTwentySeven.py', 'test.py', 'zhaobiaoInfo.py']
2015-10-05 15:29:22,736-test.py:22-testLog-执行测试 ['judgeFinish.py', 'LoginPage.py', 'manTest.py', 'message.py', 'newProject.py', 'PageCommonContent.py', 'peocessThirty.py', 'process.py', 'processFive.py', 'processOne.py', 'processSeventeen.py', 'processSix.py', 'processThirteen.py', 'processThree.py', 'processTwelve.py', 'processTwentySeven.py', 'test.py', 'zhaobiaoInfo.py']
2015-10-05 15:29:40,959-test.py:22-testLog-执行测试 ['judgeFinish.py', 'LoginPage.py', 'manTest.py', 'message.py', 'newProject.py', 'PageCommonContent.py', 'peocessThirty.py', 'process.py', 'processFive.py', 'processOne.py', 'processSeventeen.py', 'processSix.py', 'processThirteen.py', 'processThree.py', 'processTwelve.py', 'processTwentySeven.py', 'test.py', 'zhaobiaoInfo.py']
2015-10-05 15:29:48,156-test.py:22-testLog-执行测试 ['judgeFinish.py', 'LoginPage.py', 'manTest.py', 'message.py', 'newProject.py', 'PageCommonContent.py', 'peocessThirty.py', 'process.py', 'processFive.py', 'processOne.py', 'processSeventeen.py', 'processSix.py', 'processThirteen.py', 'processThree.py', 'processTwelve.py', 'processTwentySeven.py', 'test.py', 'zhaobiaoInfo.py']
2015-10-05 15:30:00,810-test.py:22-testLog-执行测试 ['judgeFinish.py', 'LoginPage.py', 'manTest.py', 'message.py', 'newProject.py', 'PageCommonContent.py', 'peocessThirty.py', 'process.py', 'processFive.py', 'processOne.py', 'processSeventeen.py', 'processSix.py', 'processThirteen.py', 'processThree.py', 'processTwelve.py', 'processTwentySeven.py', 'test.py', 'zhaobiaoInfo.py']
2015-10-05 15:30:39,530-test.py:22-testLog-执行测试 ['judgeFinish.py', 'LoginPage.py', 'manTest.py', 'message.py', 'newProject.py', 'PageCommonContent.py', 'peocessThirty.py', 'process.py', 'processFive.py', 'processOne.py', 'processSeventeen.py', 'processSix.py', 'processThirteen.py', 'processThree.py', 'processTwelve.py', 'processTwentySeven.py', 'test.py', 'zhaobiaoInfo.py']
2015-10-05 15:30:52,715-test.py:23-testLog-执行测试 ['judgeFinish.py', 'LoginPage.py', 'manTest.py', 'message.py', 'newProject.py', 'PageCommonContent.py', 'peocessThirty.py', 'process.py', 'processFive.py', 'processOne.py', 'processSeventeen.py', 'processSix.py', 'processThirteen.py', 'processThree.py', 'processTwelve.py', 'processTwentySeven.py', 'test.py', 'zhaobiaoInfo.py']
2015-10-05 15:32:13,359-test.py:23-testLog-执行测试 ['judgeFinish.py', 'LoginPage.py', 'manTest.py', 'message.py', 'newProject.py', 'PageCommonContent.py', 'peocessThirty.py', 'process.py', 'processFive.py', 'processOne.py', 'processSeventeen.py', 'processSix.py', 'processThirteen.py', 'processThree.py', 'processTwelve.py', 'processTwentySeven.py', 'test.py', 'zhaobiaoInfo.py']
2015-10-05 15:34:50,984-test.py:23-testLog-执行测试 ['judgeFinish.py', 'LoginPage.py', 'manTest.py', 'message.py', 'newProject.py', 'PageCommonContent.py', 'peocessThirty.py', 'process.py', 'processFive.py', 'processOne.py', 'processSeventeen.py', 'processSix.py', 'processThirteen.py', 'processThree.py', 'processTwelve.py', 'processTwentySeven.py', 'test.py', 'zhaobiaoInfo.py']
2015-10-05 15:35:28,606-test.py:23-testLog-执行测试 ['judgeFinish.py', 'LoginPage.py', 'manTest.py', 'message.py', 'newProject.py', 'PageCommonContent.py', 'peocessThirty.py', 'process.py', 'processFive.py', 'processOne.py', 'processSeventeen.py', 'processSix.py', 'processThirteen.py', 'processThree.py', 'processTwelve.py', 'processTwentySeven.py', 'test.py', 'zhaobiaoInfo.py']
2015-10-05 15:35:47,993-test.py:23-testLog-执行测试 ['judgeFinish.py', 'LoginPage.py', 'manTest.py', 'message.py', 'newProject.py', 'PageCommonContent.py', 'peocessThirty.py', 'process.py', 'processFive.py', 'processOne.py', 'processSeventeen.py', 'processSix.py', 'processThirteen.py', 'processThree.py', 'processTwelve.py', 'processTwentySeven.py', 'test.py', 'zhaobiaoInfo.py']
2015-10-05 15:36:00,720-test.py:23-testLog-执行测试 ['judgeFinish.py', 'LoginPage.py', 'manTest.py', 'message.py', 'newProject.py', 'PageCommonContent.py', 'peocessThirty.py', 'process.py', 'processFive.py', 'processOne.py', 'processSeventeen.py', 'processSix.py', 'processThirteen.py', 'processThree.py', 'processTwelve.py', 'processTwentySeven.py', 'test.py', 'zhaobiaoInfo.py']
2015-10-05 15:36:09,095-test.py:23-testLog-执行测试 ['judgeFinish.py', 'LoginPage.py', 'manTest.py', 'message.py', 'newProject.py', 'PageCommonContent.py', 'peocessThirty.py', 'process.py', 'processFive.py', 'processOne.py', 'processSeventeen.py', 'processSix.py', 'processThirteen.py', 'processThree.py', 'processTwelve.py', 'processTwentySeven.py', 'test.py', 'zhaobiaoInfo.py']
2015-10-05 15:36:17,954-test.py:23-testLog-执行测试 ['judgeFinish.py', 'LoginPage.py', 'manTest.py', 'message.py', 'newProject.py', 'PageCommonContent.py', 'peocessThirty.py', 'process.py', 'processFive.py', 'processOne.py', 'processSeventeen.py', 'processSix.py', 'processThirteen.py', 'processThree.py', 'processTwelve.py', 'processTwentySeven.py', 'test.py', 'zhaobiaoInfo.py']
2015-10-05 15:36:44,475-test.py:23-testLog-执行测试 ['judgeFinish.py', 'LoginPage.py', 'manTest.py', 'message.py', 'newProject.py', 'PageCommonContent.py', 'peocessThirty.py', 'process.py', 'processFive.py', 'processOne.py', 'processSeventeen.py', 'processSix.py', 'processThirteen.py', 'processThree.py', 'processTwelve.py', 'processTwentySeven.py', 'test.py', 'zhaobiaoInfo.py']
2015-10-05 15:42:15,074-test.py:24-testLog-执行测试 ['judgeFinish.py', 'LoginPage.py', 'manTest.py', 'message.py', 'newProject.py', 'PageCommonContent.py', 'peocessThirty.py', 'process.py', 'processFive.py', 'processOne.py', 'processSeventeen.py', 'processSix.py', 'processThirteen.py', 'processThree.py', 'processTwelve.py', 'processTwentySeven.py', 'test.py', 'zhaobiaoInfo.py']
2015-10-05 15:42:32,385-test.py:24-testLog-执行测试 ['judgeFinish.py', 'LoginPage.py', 'manTest.py', 'message.py', 'newProject.py', 'PageCommonContent.py', 'peocessThirty.py', 'process.py', 'processFive.py', 'processOne.py', 'processSeventeen.py', 'processSix.py', 'processThirteen.py', 'processThree.py', 'processTwelve.py', 'processTwentySeven.py', 'test.py', 'zhaobiaoInfo.py']
2015-10-05 15:42:43,573-test.py:24-testLog-执行测试 ['judgeFinish.py', 'LoginPage.py', 'manTest.py', 'message.py', 'newProject.py', 'PageCommonContent.py', 'peocessThirty.py', 'process.py', 'processFive.py', 'processOne.py', 'processSeventeen.py', 'processSix.py', 'processThirteen.py', 'processThree.py', 'processTwelve.py', 'processTwentySeven.py', 'test.py', 'zhaobiaoInfo.py']
2015-10-05 15:42:59,519-test.py:24-testLog-执行测试 ['judgeFinish.py', 'LoginPage.py', 'manTest.py', 'message.py', 'newProject.py', 'PageCommonContent.py', 'peocessThirty.py', 'process.py', 'processFive.py', 'processOne.py', 'processSeventeen.py', 'processSix.py', 'processThirteen.py', 'processThree.py', 'processTwelve.py', 'processTwentySeven.py', 'test.py', 'zhaobiaoInfo.py']
2015-10-05 15:43:42,702-test.py:24-testLog-执行测试 ['judgeFinish.py', 'LoginPage.py', 'manTest.py', 'message.py', 'newProject.py', 'PageCommonContent.py', 'peocessThirty.py', 'process.py', 'processFive.py', 'processOne.py', 'processSeventeen.py', 'processSix.py', 'processThirteen.py', 'processThree.py', 'processTwelve.py', 'processTwentySeven.py', 'test.py', 'zhaobiaoInfo.py']
2015-10-05 15:44:12,062-test.py:24-testLog-执行测试 ['judgeFinish.py', 'LoginPage.py', 'manTest.py', 'message.py', 'newProject.py', 'PageCommonContent.py', 'peocessThirty.py', 'process.py', 'processFive.py', 'processOne.py', 'processSeventeen.py', 'processSix.py', 'processThirteen.py', 'processThree.py', 'processTwelve.py', 'processTwentySeven.py', 'test.py', 'zhaobiaoInfo.py']
2015-10-05 15:45:07,610-test.py:24-testLog-执行测试 ['judgeFinish.py', 'LoginPage.py', 'manTest.py', 'message.py', 'newProject.py', 'PageCommonContent.py', 'peocessThirty.py', 'process.py', 'processFive.py', 'processOne.py', 'processSeventeen.py', 'processSix.py', 'processThirteen.py', 'processThree.py', 'processTwelve.py', 'processTwentySeven.py', 'test.py', 'zhaobiaoInfo.py']
2015-10-05 15:45:17,710-test.py:24-testLog-执行测试 ['judgeFinish.py', 'LoginPage.py', 'manTest.py', 'message.py', 'newProject.py', 'PageCommonContent.py', 'peocessThirty.py', 'process.py', 'processFive.py', 'processOne.py', 'processSeventeen.py', 'processSix.py', 'processThirteen.py', 'processThree.py', 'processTwelve.py', 'processTwentySeven.py', 'test.py', 'zhaobiaoInfo.py']
2015-10-05 15:46:07,235-test.py:24-testLog-执行测试 ['judgeFinish.py', 'LoginPage.py', 'manTest.py', 'message.py', 'newProject.py', 'PageCommonContent.py', 'peocessThirty.py', 'process.py', 'processFive.py', 'processOne.py', 'processSeventeen.py', 'processSix.py', 'processThirteen.py', 'processThree.py', 'processTwelve.py', 'processTwentySeven.py', 'test.py', 'zhaobiaoInfo.py']
2015-10-05 15:46:16,723-test.py:24-testLog-执行测试 ['judgeFinish.py', 'LoginPage.py', 'manTest.py', 'message.py', 'newProject.py', 'PageCommonContent.py', 'peocessThirty.py', 'process.py', 'processFive.py', 'processOne.py', 'processSeventeen.py', 'processSix.py', 'processThirteen.py', 'processThree.py', 'processTwelve.py', 'processTwentySeven.py', 'test.py', 'zhaobiaoInfo.py']
2015-10-05 20:28:03,100-test.py:26-testLog-执行测试 ['judgeFinish.py', 'LoginPage.py', 'manTest.py', 'message.py', 'newProject.py', 'PageCommonContent.py', 'peocessThirty.py', 'process.py', 'processFive.py', 'processOne.py', 'processSeventeen.py', 'processSix.py', 'processThirteen.py', 'processThree.py', 'processTwelve.py', 'processTwentySeven.py', 'test.py', 'zhaobiaoInfo.py']
2015-10-05 20:29:58,386-test.py:26-testLog-执行测试 ['dirFileOne.py']
2015-10-05 20:30:56,368-test.py:26-testLog-执行测试 ['dirFileOne.py']
2015-10-05 20:31:17,910-test.py:26-testLog-执行测试 ['dirFileOne.py']
2015-10-05 20:33:37,923-test.py:26-testLog-执行测试 ['dirFileOne.py']
2015-10-05 20:33:54,811-test.py:26-testLog-执行测试 ['dirFileOne.py']
2015-10-05 20:42:00,001-test.py:25-testLog-执行测试 ['dirFileOne.py']
2015-10-05 21:29:39,761-test.py:25-testLog- 
2015-10-05 21:29:39,763-test.py:26-testLog-本次执行测试 ['dirFileOne.py', 'testBase.py']
2015-10-05 21:29:39,764-test.py:30-testLog-执行dirFileOne
2015-10-05 21:30:08,444-test.py:25-testLog- 
2015-10-05 21:30:08,444-test.py:26-testLog-本次执行测试 ['dirFileOne.py', 'testBase.py']
2015-10-05 21:30:08,445-test.py:30-testLog-执行dirFileOne
2015-10-05 21:30:37,801-test.py:25-testLog- 
2015-10-05 21:30:37,801-test.py:26-testLog-本次执行测试 ['dirFileOne.py', 'testBase.py']
2015-10-05 21:30:37,802-test.py:30-testLog-执行dirFileOne
2015-10-05 21:30:37,807-test.py:30-testLog-执行testBase
2015-10-05 21:34:26,708-test.py:25-testLog- 
2015-10-05 21:34:26,708-test.py:26-testLog-本次执行测试 ['dirFileOne.py', 'testBase.py']
2015-10-05 21:34:26,709-test.py:30-testLog-执行dirFileOne
2015-10-05 21:34:26,714-test.py:30-testLog-执行testBase
2015-10-05 21:37:48,242-test.py:26-testLog- 
2015-10-05 21:37:48,242-test.py:27-testLog-本次执行测试 ['dirFileOne.py', 'testBase.py']
2015-10-05 21:37:48,243-test.py:31-testLog-执行dirFileOne
2015-10-05 21:37:48,245-test.py:31-testLog-执行testBase
2015-10-05 21:38:02,746-test.py:26-testLog- 
2015-10-05 21:38:02,746-test.py:27-testLog-本次执行测试 ['dirFileOne.py', 'testBase.py']
2015-10-05 21:38:02,747-test.py:31-testLog-执行dirFileOne
2015-10-05 21:38:02,748-test.py:31-testLog-执行testBase
2015-10-05 21:38:27,573-test.py:26-testLog- 
2015-10-05 21:38:27,573-test.py:27-testLog-本次执行测试 ['dirFileOne.py', 'testBase.py']
2015-10-05 21:38:27,574-test.py:31-testLog-执行dirFileOne
2015-10-05 21:38:27,574-test.py:31-testLog-执行testBase
2015-10-05 22:00:27,421-test.py:26-testLog- 
2015-10-05 22:00:27,421-test.py:27-testLog-本次执行测试 ['dirFileOne.py', 'testBase.py']
2015-10-05 22:00:27,421-test.py:40-testLog-执行dirFileOne
2015-10-05 22:00:27,423-test.py:52-testLog-ui测试dirFileOne成功
2015-10-05 22:00:27,423-test.py:40-testLog-执行testBase
2015-10-05 22:00:27,423-test.py:52-testLog-ui测试testBase成功
2015-10-05 22:18:56,177-test.py:26-testLog- 
2015-10-05 22:18:56,177-test.py:27-testLog-本次执行测试 ['dirFileOne.py', 'testBase.py']
2015-10-05 22:18:56,178-test.py:57-testLog-执行dirFileOne
2015-10-05 22:18:56,179-test.py:66-testLog-ui测试dirFileOne失败
2015-10-05 22:18:56,179-test.py:57-testLog-执行testBase
2015-10-05 22:18:56,180-test.py:66-testLog-ui测试testBase失败
2015-10-05 22:19:14,183-test.py:26-testLog- 
2015-10-05 22:19:14,183-test.py:27-testLog-本次执行测试 ['dirFileOne.py', 'testBase.py']
2015-10-05 22:19:14,183-test.py:57-testLog-执行dirFileOne
2015-10-05 22:19:14,184-test.py:66-testLog-ui测试dirFileOne失败
2015-10-05 22:19:14,184-test.py:57-testLog-执行testBase
2015-10-05 22:19:14,185-test.py:66-testLog-ui测试testBase失败
2015-10-05 22:20:03,142-test.py:26-testLog- 
2015-10-05 22:20:03,143-test.py:27-testLog-本次执行测试 ['dirFileOne.py', 'testBase.py']
2015-10-05 22:20:03,143-test.py:57-testLog-执行dirFileOne
2015-10-05 22:20:03,144-test.py:66-testLog-ui测试dirFileOne失败
2015-10-05 22:20:03,144-test.py:57-testLog-执行testBase
2015-10-05 22:20:03,144-test.py:66-testLog-ui测试testBase失败
2015-10-05 22:42:42,189-test.py:26-testLog- 
2015-10-05 22:42:42,189-test.py:27-testLog-本次执行测试 ['dirFileOne.py', 'testBase.py']
2015-10-05 22:42:42,190-test.py:57-testLog-执行dirFileOne
2015-10-05 22:42:42,191-test.py:68-testLog-ui测试dirFileOne成功
2015-10-05 22:42:42,191-test.py:57-testLog-执行testBase
2015-10-05 22:42:42,192-test.py:68-testLog-ui测试testBase成功
2015-10-05 22:42:58,044-test.py:26-testLog- 
2015-10-05 22:42:58,044-test.py:27-testLog-本次执行测试 ['dirFileOne.py', 'testBase.py']
2015-10-05 22:42:58,044-test.py:57-testLog-执行dirFileOne
2015-10-05 22:42:58,045-test.py:68-testLog-ui测试dirFileOne成功
2015-10-05 22:42:58,045-test.py:57-testLog-执行testBase
2015-10-05 22:42:58,045-test.py:68-testLog-ui测试testBase成功
2015-10-05 22:43:24,945-test.py:26-testLog- 
2015-10-05 22:43:24,945-test.py:27-testLog-本次执行测试 ['dirFileOne.py', 'testBase.py']
2015-10-05 22:43:24,946-test.py:57-testLog-执行dirFileOne
2015-10-05 22:43:24,946-test.py:68-testLog-ui测试dirFileOne成功
2015-10-05 22:43:24,946-test.py:57-testLog-执行testBase
2015-10-05 22:43:24,946-test.py:68-testLog-ui测试testBase成功
2015-10-05 22:43:35,572-test.py:26-testLog- 
2015-10-05 22:43:35,572-test.py:27-testLog-本次执行测试 ['dirFileOne.py', 'testBase.py']
2015-10-05 22:43:35,572-test.py:57-testLog-执行dirFileOne
2015-10-05 22:43:35,573-test.py:66-testLog-ui测试dirFileOne失败
2015-10-05 22:43:35,573-test.py:57-testLog-执行testBase
2015-10-05 22:43:35,574-test.py:66-testLog-ui测试testBase失败
2015-10-05 22:43:53,292-test.py:26-testLog- 
2015-10-05 22:43:53,292-test.py:27-testLog-本次执行测试 ['dirFileOne.py', 'testBase.py']
2015-10-05 22:43:53,293-test.py:57-testLog-执行dirFileOne
2015-10-05 22:43:53,293-test.py:66-testLog-ui测试dirFileOne失败
2015-10-05 22:43:53,293-test.py:57-testLog-执行testBase
2015-10-05 22:43:53,293-test.py:66-testLog-ui测试testBase失败
2015-10-05 22:44:56,797-test.py:26-testLog- 
2015-10-05 22:44:56,797-test.py:27-testLog-本次执行测试 ['dirFileOne.py', 'testBase.py']
2015-10-05 22:44:56,797-test.py:57-testLog-执行dirFileOne
2015-10-05 22:44:56,799-test.py:66-testLog-ui测试dirFileOne失败
2015-10-05 22:44:56,799-test.py:57-testLog-执行testBase
2015-10-05 22:44:56,800-test.py:66-testLog-ui测试testBase失败
2015-10-05 22:45:10,993-test.py:26-testLog- 
2015-10-05 22:45:10,993-test.py:27-testLog-本次执行测试 ['dirFileOne.py', 'testBase.py']
2015-10-05 22:45:10,994-test.py:57-testLog-执行dirFileOne
2015-10-05 22:45:10,994-test.py:66-testLog-ui测试dirFileOne失败
2015-10-05 22:45:10,994-test.py:57-testLog-执行testBase
2015-10-05 22:45:10,994-test.py:66-testLog-ui测试testBase失败
2015-10-05 22:45:47,862-test.py:26-testLog- 
2015-10-05 22:45:47,862-test.py:27-testLog-本次执行测试 ['dirFileOne.py', 'testBase.py']
2015-10-05 22:45:47,862-test.py:57-testLog-执行dirFileOne
2015-10-05 22:45:47,863-test.py:66-testLog-ui测试dirFileOne失败
2015-10-05 22:45:47,863-test.py:57-testLog-执行testBase
2015-10-05 22:45:47,863-test.py:66-testLog-ui测试testBase失败
2015-10-05 22:45:58,069-test.py:26-testLog- 
2015-10-05 22:45:58,069-test.py:27-testLog-本次执行测试 ['dirFileOne.py', 'testBase.py']
2015-10-05 22:45:58,069-test.py:57-testLog-执行dirFileOne
2015-10-05 22:45:58,070-test.py:66-testLog-ui测试dirFileOne失败
2015-10-05 22:45:58,070-test.py:57-testLog-执行testBase
2015-10-05 22:45:58,070-test.py:66-testLog-ui测试testBase失败
2015-10-05 22:46:35,040-test.py:26-testLog- 
2015-10-05 22:46:35,040-test.py:27-testLog-本次执行测试 ['dirFileOne.py', 'testBase.py']
2015-10-05 22:46:35,040-test.py:57-testLog-执行dirFileOne
2015-10-05 22:46:35,041-test.py:66-testLog-ui测试dirFileOne失败
2015-10-05 22:46:35,041-test.py:57-testLog-执行testBase
2015-10-05 22:46:35,041-test.py:66-testLog-ui测试testBase失败
2015-10-05 22:47:14,365-test.py:26-testLog- 
2015-10-05 22:47:14,365-test.py:27-testLog-本次执行测试 ['dirFileOne.py', 'testBase.py']
2015-10-05 22:47:14,366-test.py:57-testLog-执行dirFileOne
2015-10-05 22:47:14,366-test.py:66-testLog-ui测试dirFileOne失败
2015-10-05 22:47:14,366-test.py:57-testLog-执行testBase
2015-10-05 22:47:14,367-test.py:66-testLog-ui测试testBase失败
2015-10-05 22:50:07,185-test.py:26-testLog- 
2015-10-05 22:50:07,185-test.py:27-testLog-本次执行测试 ['dirFileOne.py', 'testBase.py']
2015-10-05 22:50:07,185-test.py:60-testLog-执行dirFileOne
2015-10-05 22:50:07,186-test.py:69-testLog-ui测试dirFileOne失败
2015-10-05 22:50:07,186-test.py:60-testLog-执行testBase
2015-10-05 22:50:07,186-test.py:69-testLog-ui测试testBase失败
2015-10-05 22:51:28,895-test.py:26-testLog- 
2015-10-05 22:51:28,895-test.py:27-testLog-本次执行测试 ['dirFileOne.py', 'testBase.py']
2015-10-05 22:51:28,895-test.py:60-testLog-执行dirFileOne
2015-10-05 22:51:28,896-test.py:69-testLog-ui测试dirFileOne失败
2015-10-05 22:51:28,897-test.py:60-testLog-执行testBase
2015-10-05 22:51:28,897-test.py:69-testLog-ui测试testBase失败
2015-10-05 23:07:26,759-test.py:26-testLog- 
2015-10-05 23:07:26,760-test.py:27-testLog-本次执行测试 ['dirFileOne.py', 'testBase.py']
2015-10-05 23:07:52,603-test.py:26-testLog- 
2015-10-05 23:07:52,604-test.py:27-testLog-本次执行测试 ['dirFileOne.py', 'testBase.py']
2015-10-05 23:07:52,604-test.py:60-testLog-执行dirFileOne
2015-10-05 23:07:52,606-test.py:69-testLog-ui测试dirFileOne失败
2015-10-05 23:07:52,606-test.py:60-testLog-执行testBase
2015-10-05 23:07:52,606-test.py:69-testLog-ui测试testBase失败
2015-10-05 23:11:47,847-test.py:26-testLog- 
2015-10-05 23:11:47,848-test.py:27-testLog-本次执行测试 ['dirFileOne.py', 'testBase.py']
2015-10-05 23:11:47,849-test.py:60-testLog-执行dirFileOne
2015-10-05 23:11:47,850-test.py:69-testLog-ui测试dirFileOne失败
2015-10-05 23:11:47,850-test.py:60-testLog-执行testBase
2015-10-05 23:11:47,851-test.py:69-testLog-ui测试testBase失败
2015-10-05 23:12:13,140-test.py:26-testLog- 
2015-10-05 23:12:13,141-test.py:27-testLog-本次执行测试 ['dirFileOne.py', 'testBase.py']
2015-10-05 23:12:13,141-test.py:60-testLog-执行dirFileOne
2015-10-05 23:12:13,142-test.py:69-testLog-ui测试dirFileOne失败
2015-10-05 23:12:13,142-test.py:60-testLog-执行testBase
2015-10-05 23:12:13,142-test.py:69-testLog-ui测试testBase失败
2015-10-06 10:39:30,120-test.py:26-testLog- 
2015-10-06 10:39:30,120-test.py:27-testLog-本次执行测试 ['dirFileOne.py', 'testBase.py']
2015-10-06 10:39:30,121-test.py:60-testLog-执行dirFileOne
2015-10-06 10:39:30,121-test.py:69-testLog-ui测试dirFileOne失败
2015-10-06 10:39:30,121-test.py:60-testLog-执行testBase
2015-10-06 10:39:30,122-test.py:69-testLog-ui测试testBase失败
2015-10-06 10:39:58,144-test.py:26-testLog- 
2015-10-06 10:39:58,144-test.py:27-testLog-本次执行测试 ['dirFileOne.py', 'testBase.py']
2015-10-06 10:39:58,144-test.py:60-testLog-执行dirFileOne
2015-10-06 10:39:58,146-test.py:69-testLog-ui测试dirFileOne失败
2015-10-06 10:39:58,147-test.py:60-testLog-执行testBase
2015-10-06 10:39:58,148-test.py:69-testLog-ui测试testBase失败
2015-10-06 10:40:05,506-test.py:26-testLog- 
2015-10-06 10:40:05,506-test.py:27-testLog-本次执行测试 ['dirFileOne.py', 'testBase.py']
2015-10-06 10:40:05,507-test.py:60-testLog-执行dirFileOne
2015-10-06 10:40:05,507-test.py:69-testLog-ui测试dirFileOne失败
2015-10-06 10:40:05,507-test.py:60-testLog-执行testBase
2015-10-06 10:40:05,507-test.py:69-testLog-ui测试testBase失败
2015-10-06 10:41:05,566-test.py:26-testLog- 
2015-10-06 10:41:05,566-test.py:27-testLog-本次执行测试 ['dirFileOne.py', 'testBase.py']
2015-10-06 10:41:05,566-test.py:60-testLog-执行dirFileOne
2015-10-06 10:41:05,567-test.py:69-testLog-ui测试dirFileOne失败
2015-10-06 10:41:05,567-test.py:60-testLog-执行testBase
2015-10-06 10:41:05,567-test.py:69-testLog-ui测试testBase失败
2015-10-06 10:41:25,664-test.py:26-testLog- 
2015-10-06 10:41:25,664-test.py:27-testLog-本次执行测试 ['dirFileOne.py', 'testBase.py']
2015-10-06 10:41:25,664-test.py:60-testLog-执行dirFileOne
2015-10-06 10:41:25,664-test.py:69-testLog-ui测试dirFileOne失败
2015-10-06 10:41:25,664-test.py:60-testLog-执行testBase
2015-10-06 10:41:25,665-test.py:69-testLog-ui测试testBase失败
2015-10-06 10:43:36,600-test.py:26-testLog- 
2015-10-06 10:43:36,600-test.py:27-testLog-本次执行测试 ['dirFileOne.py', 'testBase.py']
2015-10-06 10:43:36,600-test.py:60-testLog-执行dirFileOne
2015-10-06 10:43:36,601-test.py:69-testLog-ui测试dirFileOne失败
2015-10-06 10:43:36,601-test.py:60-testLog-执行testBase
2015-10-06 10:43:36,601-test.py:69-testLog-ui测试testBase失败
2015-10-06 10:44:17,609-test.py:26-testLog- 
2015-10-06 10:44:17,609-test.py:27-testLog-本次执行测试 ['dirFileOne.py', 'testBase.py']
2015-10-06 10:44:17,611-test.py:60-testLog-执行dirFileOne
2015-10-06 10:44:17,611-test.py:69-testLog-ui测试dirFileOne失败
2015-10-06 10:44:17,612-test.py:60-testLog-执行testBase
2015-10-06 10:44:17,612-test.py:69-testLog-ui测试testBase失败
2015-10-06 10:48:08,106-test.py:26-testLog- 
2015-10-06 10:48:08,107-test.py:27-testLog-本次执行测试 ['dirFileOne.py', 'testBase.py']
2015-10-06 10:48:08,107-test.py:60-testLog-执行dirFileOne
2015-10-06 10:48:08,108-test.py:69-testLog-ui测试dirFileOne失败
2015-10-06 10:48:08,108-test.py:60-testLog-执行testBase
2015-10-06 10:48:08,108-test.py:69-testLog-ui测试testBase失败
2015-10-06 10:55:30,598-test.py:26-testLog- 
2015-10-06 10:55:30,598-test.py:27-testLog-本次执行测试 ['dirFileOne.py', 'testBase.py']
2015-10-06 10:55:30,598-test.py:60-testLog-执行dirFileOne
2015-10-06 10:55:30,599-test.py:69-testLog-ui测试dirFileOne失败
2015-10-06 10:55:30,599-test.py:60-testLog-执行testBase
2015-10-06 10:55:30,599-test.py:69-testLog-ui测试testBase失败
2015-10-06 11:23:17,512-test.py:26-testLog- 
2015-10-06 11:23:17,513-test.py:27-testLog-本次执行测试 ['dirFileOne.py', 'testBase.py']
2015-10-06 11:23:17,513-test.py:60-testLog-执行dirFileOne
2015-10-06 11:23:17,513-test.py:69-testLog-ui测试dirFileOne失败
2015-10-06 11:23:17,514-test.py:60-testLog-执行testBase
2015-10-06 11:23:17,514-test.py:69-testLog-ui测试testBase失败
2015-10-06 11:54:22,719-test.py:26-testLog- 
2015-10-06 11:54:22,719-test.py:27-testLog-本次执行测试 ['dirFileOne.py', 'testBase.py']
2015-10-06 11:54:22,720-test.py:60-testLog-执行dirFileOne
2015-10-06 11:54:22,721-test.py:69-testLog-ui测试dirFileOne失败
2015-10-06 11:54:22,721-test.py:60-testLog-执行testBase
2015-10-06 11:54:22,722-test.py:69-testLog-ui测试testBase失败
2015-10-06 11:57:55,436-test.py:26-testLog- 
2015-10-06 11:57:55,437-test.py:27-testLog-本次执行测试 ['dirFileOne.py', 'testBase.py']
2015-10-06 11:57:55,438-test.py:60-testLog-执行dirFileOne
2015-10-06 11:57:55,439-test.py:69-testLog-ui测试dirFileOne失败
2015-10-06 11:57:55,439-test.py:60-testLog-执行testBase
2015-10-06 11:57:55,440-test.py:69-testLog-ui测试testBase失败
2015-10-06 12:06:15,793-test.py:26-testLog- 
2015-10-06 12:06:15,793-test.py:27-testLog-本次执行测试 ['dirFileOne.py', 'testBase.py']
2015-10-06 12:06:15,793-test.py:60-testLog-执行dirFileOne
2015-10-06 12:06:15,795-test.py:69-testLog-ui测试dirFileOne失败
2015-10-06 12:06:15,795-test.py:60-testLog-执行testBase
2015-10-06 12:06:15,796-test.py:69-testLog-ui测试testBase失败
2015-10-06 12:09:07,469-test.py:26-testLog- 
2015-10-06 12:09:07,469-test.py:27-testLog-本次执行测试 ['dirFileOne.py', 'testBase.py']
2015-10-06 12:09:07,469-test.py:60-testLog-执行dirFileOne
2015-10-06 12:09:07,470-test.py:69-testLog-ui测试dirFileOne失败
2015-10-06 12:09:07,470-test.py:60-testLog-执行testBase
2015-10-06 12:09:07,470-test.py:69-testLog-ui测试testBase失败
2015-10-06 12:09:08,948-testLogic.py:43-testLog-今天的测试任务出现了bug
2015-10-06 12:09:38,477-testLogic.py:43-testLog-今天的测试任务出现了bug
2015-10-06 12:09:40,764-testLogic.py:43-testLog-今天的测试任务出现了bug
2015-10-06 12:09:40,968-testLogic.py:43-testLog-今天的测试任务出现了bug
2015-10-06 12:09:41,144-testLogic.py:43-testLog-今天的测试任务出现了bug
2015-10-06 12:13:33,356-test.py:25-testLog- 
2015-10-06 12:13:33,356-test.py:26-testLog-本次执行测试 ['dirFileOne.py', 'testBase.py']
2015-10-06 12:13:33,356-test.py:59-testLog-执行dirFileOne
2015-10-06 12:13:33,357-test.py:68-testLog-ui测试dirFileOne失败
2015-10-06 12:13:33,357-test.py:59-testLog-执行testBase
2015-10-06 12:13:33,357-test.py:68-testLog-ui测试testBase失败
2015-10-06 12:13:35,293-testLogic.py:42-testLog-今天的测试任务出现了bug
2015-10-06 12:13:49,307-testLogic.py:42-testLog-今天的测试任务出现了bug
2015-10-06 12:13:52,279-testLogic.py:42-testLog-今天的测试任务出现了bug
2015-10-06 12:27:47,664-test.py:25-testLog- 
2015-10-06 12:27:47,664-test.py:26-testLog-本次执行测试 ['dirFileOne.py', 'testBase.py']
2015-10-06 12:27:47,665-test.py:59-testLog-执行dirFileOne
2015-10-06 12:27:47,666-test.py:68-testLog-ui测试dirFileOne失败
2015-10-06 12:27:47,666-test.py:59-testLog-执行testBase
2015-10-06 12:27:47,667-test.py:68-testLog-ui测试testBase失败
2015-10-06 12:27:49,124-testLogic.py:43-testLog-今天的测试任务出现了bug
2015-10-06 12:27:49,124-testLogic.py:44-testLog-Traceback (most recent call last):
  File "testLogic.py", line 41, in run
    runTest()
  File "testLogic.py", line 12, in runTest
    oneTest.sendMail()
  File "/Users/xiyuanbupt/PycharmProjects/yunZhaoBiao/manage/test.py", line 94, in sendMail
    receiverEmail=EmailAdd[key]
KeyError: u'zhongtianlong'

2015-10-06 12:43:26,162-test.py:25-testLog- 
2015-10-06 12:43:26,162-test.py:26-testLog-本次执行测试 ['dirFileOne.py', 'testBase.py']
2015-10-06 12:43:26,162-test.py:59-testLog-执行dirFileOne
2015-10-06 12:43:26,164-test.py:68-testLog-ui测试dirFileOne失败
2015-10-06 12:43:26,165-test.py:59-testLog-执行testBase
2015-10-06 12:43:26,165-test.py:68-testLog-ui测试testBase失败
2015-10-06 12:43:27,731-testLogic.py:43-testLog-今天的测试任务出现了bug
2015-10-06 12:43:27,732-testLogic.py:44-testLog-Traceback (most recent call last):
  File "testLogic.py", line 41, in run
    runTest()
  File "testLogic.py", line 12, in runTest
    oneTest.sendMail()
  File "/Users/xiyuanbupt/PycharmProjects/yunZhaoBiao/manage/test.py", line 94, in sendMail
    receiverEmail=EmailAdd[key]
KeyError: u'zhongtianlong'

2015-10-14 15:55:28,469-test.py:25-testLog- 
2015-10-14 15:55:28,471-test.py:26-testLog-本次执行测试 ['dirFileOne.py', 'testBase.py']
2015-10-14 15:55:28,471-test.py:59-testLog-执行dirFileOne
2015-10-14 15:55:28,472-test.py:68-testLog-ui测试dirFileOne失败
2015-10-14 15:55:28,473-test.py:59-testLog-执行testBase
2015-10-14 15:55:28,474-test.py:68-testLog-ui测试testBase失败
2015-10-14 15:55:30,789-testLogic.py:43-testLog-今天的测试任务出现了bug
2015-10-14 15:55:30,791-testLogic.py:44-testLog-Traceback (most recent call last):
  File "testLogic.py", line 41, in run
    runTest()
  File "testLogic.py", line 12, in runTest
    oneTest.sendMail()
  File "/Users/xiyuanbupt/PycharmProjects/yunZhaoBiao/manage/test.py", line 94, in sendMail
    receiverEmail=EmailAdd[key]
KeyError: u'zhongtianlong'

2015-10-26 11:17:18,553-test.py:25-testLog- 
2015-10-26 11:17:18,554-test.py:26-testLog-本次执行测试 ['dirFileOne.py', 'testBase.py']
2015-10-26 11:17:18,554-test.py:59-testLog-执行dirFileOne
2015-10-26 11:17:18,556-test.py:68-testLog-ui测试dirFileOne失败
2015-10-26 11:17:18,556-test.py:59-testLog-执行testBase
2015-10-26 11:17:18,556-test.py:68-testLog-ui测试testBase失败
2015-10-26 11:17:18,984-testLogic.py:43-testLog-今天的测试任务出现了bug
2015-10-26 11:17:18,986-testLogic.py:44-testLog-Traceback (most recent call last):
  File "testLogic.py", line 41, in run
    runTest()
  File "testLogic.py", line 12, in runTest
    oneTest.sendMail()
  File "/Users/xiyuanbupt/PycharmProjects/yunZhaoBiao/manage/test.py", line 96, in sendMail
    SmtpEmailSender().sendEmailTo(receiverEmail,a.html)
  File "/Users/xiyuanbupt/PycharmProjects/yunZhaoBiao/conf/conf.py", line 61, in sendEmailTo
    smtp.login(self.username,self.password)
  File "/System/Library/Frameworks/Python.framework/Versions/2.7/lib/python2.7/smtplib.py", line 622, in login
    raise SMTPAuthenticationError(code, resp)
SMTPAuthenticationError: (535, 'Error: authentication failed, system busy')

2015-10-26 11:17:59,469-test.py:25-testLog- 
2015-10-26 11:17:59,469-test.py:26-testLog-本次执行测试 ['dirFileOne.py', 'testBase.py']
2015-10-26 11:17:59,470-test.py:59-testLog-执行dirFileOne
2015-10-26 11:17:59,470-test.py:68-testLog-ui测试dirFileOne失败
2015-10-26 11:17:59,471-test.py:59-testLog-执行testBase
2015-10-26 11:17:59,471-test.py:68-testLog-ui测试testBase失败
2015-10-26 11:18:01,312-testLogic.py:43-testLog-今天的测试任务出现了bug
2015-10-26 11:18:01,313-testLogic.py:44-testLog-Traceback (most recent call last):
  File "testLogic.py", line 41, in run
    runTest()
  File "testLogic.py", line 12, in runTest
    oneTest.sendMail()
  File "/Users/xiyuanbupt/PycharmProjects/yunZhaoBiao/manage/test.py", line 94, in sendMail
    receiverEmail=EmailAdd[key]
KeyError: u'zhongtianlong'

2015-10-26 11:20:17,943-test.py:25-testLog- 
2015-10-26 11:20:17,943-test.py:26-testLog-本次执行测试 ['dirFileOne.py', 'testBase.py']
2015-10-26 11:20:17,944-test.py:59-testLog-执行dirFileOne
2015-10-26 11:20:17,945-test.py:68-testLog-ui测试dirFileOne失败
2015-10-26 11:20:17,945-test.py:59-testLog-执行testBase
2015-10-26 11:20:17,945-test.py:68-testLog-ui测试testBase失败
2015-10-26 11:20:19,572-testLogic.py:43-testLog-今天的测试任务出现了bug
2015-10-26 11:20:19,573-testLogic.py:44-testLog-Traceback (most recent call last):
  File "/Users/xiyuanbupt/PycharmProjects/yunZhaoBiao/testLogic.py", line 41, in run
    runTest()
  File "/Users/xiyuanbupt/PycharmProjects/yunZhaoBiao/testLogic.py", line 12, in runTest
    oneTest.sendMail()
  File "/Users/xiyuanbupt/PycharmProjects/yunZhaoBiao/manage/test.py", line 94, in sendMail
    receiverEmail=EmailAdd[key]
KeyError: u'zhongtianlong'

2015-10-26 11:22:07,924-test.py:25-testLog- 
2015-10-26 11:22:07,925-test.py:26-testLog-本次执行测试 ['dirFileOne.py', 'testBase.py']
2015-10-26 11:22:07,925-test.py:59-testLog-执行dirFileOne
2015-10-26 11:22:07,927-test.py:68-testLog-ui测试dirFileOne失败
2015-10-26 11:22:07,927-test.py:59-testLog-执行testBase
2015-10-26 11:22:07,927-test.py:68-testLog-ui测试testBase失败
2015-10-26 11:22:07,927-testLogic.py:43-testLog-今天的测试任务出现了bug
2015-10-26 11:22:07,928-testLogic.py:44-testLog-Traceback (most recent call last):
  File "/Users/xiyuanbupt/PycharmProjects/yunZhaoBiao/testLogic.py", line 41, in run
    runTest()
  File "/Users/xiyuanbupt/PycharmProjects/yunZhaoBiao/testLogic.py", line 12, in runTest
    oneTest.sendMail()
  File "/Users/xiyuanbupt/PycharmProjects/yunZhaoBiao/manage/test.py", line 94, in sendMail
    receiverEmail=EmailAdd[key]
KeyError: u'zhaotianlong'

2015-10-26 11:27:41,664-test.py:25-testLog- 
2015-10-26 11:27:41,664-test.py:26-testLog-本次执行测试 ['dirFileOne.py', 'testBase.py']
2015-10-26 11:27:41,665-test.py:59-testLog-执行dirFileOne
2015-10-26 11:27:41,666-test.py:68-testLog-ui测试dirFileOne失败
2015-10-26 11:27:41,666-test.py:59-testLog-执行testBase
2015-10-26 11:27:41,667-test.py:68-testLog-ui测试testBase失败
2015-10-26 11:29:06,629-test.py:25-testLog- 
2015-10-26 11:29:06,630-test.py:26-testLog-本次执行测试 ['dirFileOne.py', 'testBase.py']
2015-10-26 11:29:06,630-test.py:59-testLog-执行dirFileOne
2015-10-26 11:29:06,631-test.py:68-testLog-ui测试dirFileOne失败
2015-10-26 11:29:06,631-test.py:59-testLog-执行testBase
2015-10-26 11:29:06,631-test.py:68-testLog-ui测试testBase失败
2015-10-26 21:14:22,219-test.py:25-testLog- 
2015-10-26 21:14:22,219-test.py:26-testLog-本次执行测试 ['dirFileOne.py', 'testBase.py']
2015-10-26 21:14:22,220-test.py:63-testLog-执行dirFileOne
2015-10-26 21:14:22,223-testLogic.py:43-testLog-今天的测试任务出现了bug
2015-10-26 21:14:22,223-testLogic.py:44-testLog-Traceback (most recent call last):
  File "testLogic.py", line 41, in run
    runTest()
  File "testLogic.py", line 11, in runTest
    oneTest.runTest()
  File "/Users/xiyuanbupt/PycharmProjects/yunZhaoBiao/manage/test.py", line 71, in runTest
    if res['res']==0:
KeyError: 'res'

2015-10-26 21:16:05,406-test.py:25-testLog- 
2015-10-26 21:16:05,406-test.py:26-testLog-本次执行测试 ['dirFileOne.py', 'testBase.py']
2015-10-26 21:16:05,406-test.py:63-testLog-执行dirFileOne
2015-10-26 21:16:05,407-testLogic.py:43-testLog-今天的测试任务出现了bug
2015-10-26 21:16:05,407-testLogic.py:44-testLog-Traceback (most recent call last):
  File "testLogic.py", line 41, in run
    runTest()
  File "testLogic.py", line 11, in runTest
    oneTest.runTest()
  File "/Users/xiyuanbupt/PycharmProjects/yunZhaoBiao/manage/test.py", line 71, in runTest
    if res['res']==0:
KeyError: 'res'

2015-10-26 21:20:35,982-test.py:25-testLog- 
2015-10-26 21:20:35,982-test.py:26-testLog-本次执行测试 ['dirFileOne.py', 'testBase.py']
2015-10-26 21:20:35,982-test.py:63-testLog-执行dirFileOne
2015-10-26 21:20:35,983-testLogic.py:43-testLog-今天的测试任务出现了bug
2015-10-26 21:20:35,984-testLogic.py:44-testLog-Traceback (most recent call last):
  File "testLogic.py", line 41, in run
    runTest()
  File "testLogic.py", line 11, in runTest
    oneTest.runTest()
  File "/Users/xiyuanbupt/PycharmProjects/yunZhaoBiao/manage/test.py", line 71, in runTest
    if res['res']==0:
KeyError: 'res'

2015-10-26 21:22:30,590-test.py:25-testLog- 
2015-10-26 21:22:30,590-test.py:26-testLog-本次执行测试 ['dirFileOne.py', 'testBase.py']
2015-10-26 21:22:30,591-test.py:63-testLog-执行dirFileOne
2015-10-26 21:22:30,591-testLogic.py:43-testLog-今天的测试任务出现了bug
2015-10-26 21:22:30,592-testLogic.py:44-testLog-Traceback (most recent call last):
  File "testLogic.py", line 41, in run
    runTest()
  File "testLogic.py", line 11, in runTest
    oneTest.runTest()
  File "/Users/xiyuanbupt/PycharmProjects/yunZhaoBiao/manage/test.py", line 71, in runTest
    if tmp['res']==0:
KeyError: 'res'

2015-10-26 21:23:04,102-test.py:25-testLog- 
2015-10-26 21:23:04,102-test.py:26-testLog-本次执行测试 ['dirFileOne.py', 'testBase.py']
2015-10-26 21:23:04,102-test.py:63-testLog-执行dirFileOne
2015-10-26 21:23:04,103-testLogic.py:43-testLog-今天的测试任务出现了bug
2015-10-26 21:23:04,104-testLogic.py:44-testLog-Traceback (most recent call last):
  File "testLogic.py", line 41, in run
    runTest()
  File "testLogic.py", line 11, in runTest
    oneTest.runTest()
  File "/Users/xiyuanbupt/PycharmProjects/yunZhaoBiao/manage/test.py", line 72, in runTest
    if tmp['res']==0:
KeyError: 'res'

2015-10-26 21:23:31,287-test.py:25-testLog- 
2015-10-26 21:23:31,287-test.py:26-testLog-本次执行测试 ['dirFileOne.py', 'testBase.py']
2015-10-26 21:23:31,287-test.py:63-testLog-执行dirFileOne
2015-10-26 21:23:31,288-testLogic.py:43-testLog-今天的测试任务出现了bug
2015-10-26 21:23:31,289-testLogic.py:44-testLog-Traceback (most recent call last):
  File "testLogic.py", line 41, in run
    runTest()
  File "testLogic.py", line 11, in runTest
    oneTest.runTest()
  File "/Users/xiyuanbupt/PycharmProjects/yunZhaoBiao/manage/test.py", line 73, in runTest
    if tmp['res']==0:
KeyError: 'res'

2015-10-26 21:25:06,718-test.py:25-testLog- 
2015-10-26 21:25:06,718-test.py:26-testLog-本次执行测试 ['dirFileOne.py', 'testBase.py']
2015-10-26 21:25:06,718-test.py:63-testLog-执行dirFileOne
2015-10-26 21:25:06,719-testLogic.py:43-testLog-今天的测试任务出现了bug
2015-10-26 21:25:06,720-testLogic.py:44-testLog-Traceback (most recent call last):
  File "testLogic.py", line 41, in run
    runTest()
  File "testLogic.py", line 11, in runTest
    oneTest.runTest()
  File "/Users/xiyuanbupt/PycharmProjects/yunZhaoBiao/manage/test.py", line 72, in runTest
    if tmp['res']==0:
KeyError: 'res'

2015-10-26 21:26:05,620-test.py:25-testLog- 
2015-10-26 21:26:05,620-test.py:26-testLog-本次执行测试 ['dirFileOne.py', 'testBase.py']
2015-10-26 21:26:05,621-test.py:63-testLog-执行dirFileOne
2015-10-26 21:26:05,622-testLogic.py:43-testLog-今天的测试任务出现了bug
2015-10-26 21:26:05,622-testLogic.py:44-testLog-Traceback (most recent call last):
  File "testLogic.py", line 41, in run
    runTest()
  File "testLogic.py", line 11, in runTest
    oneTest.runTest()
  File "/Users/xiyuanbupt/PycharmProjects/yunZhaoBiao/manage/test.py", line 73, in runTest
    if tmp['res']==0:
KeyError: 'res'

2015-10-26 21:27:20,074-test.py:25-testLog- 
2015-10-26 21:27:20,074-test.py:26-testLog-本次执行测试 ['dirFileOne.py', 'testBase.py']
2015-10-26 21:27:20,074-test.py:63-testLog-执行dirFileOne
2015-10-26 21:27:20,076-testLogic.py:43-testLog-今天的测试任务出现了bug
2015-10-26 21:27:20,076-testLogic.py:44-testLog-Traceback (most recent call last):
  File "testLogic.py", line 41, in run
    runTest()
  File "testLogic.py", line 11, in runTest
    oneTest.runTest()
  File "/Users/xiyuanbupt/PycharmProjects/yunZhaoBiao/manage/test.py", line 73, in runTest
    if tmp['res']==0:
KeyError: 'res'

2015-10-26 21:28:40,870-test.py:25-testLog- 
2015-10-26 21:28:40,871-test.py:26-testLog-本次执行测试 ['dirFileOne.py', 'testBase.py']
2015-10-26 21:28:40,871-test.py:63-testLog-执行dirFileOne
2015-10-26 21:28:40,872-testLogic.py:43-testLog-今天的测试任务出现了bug
2015-10-26 21:28:40,873-testLogic.py:44-testLog-Traceback (most recent call last):
  File "testLogic.py", line 41, in run
    runTest()
  File "testLogic.py", line 11, in runTest
    oneTest.runTest()
  File "/Users/xiyuanbupt/PycharmProjects/yunZhaoBiao/manage/test.py", line 73, in runTest
    if tmp['res']==0:
KeyError: 'res'

2015-10-26 21:29:59,337-test.py:25-testLog- 
2015-10-26 21:29:59,337-test.py:26-testLog-本次执行测试 ['dirFileOne.py', 'testBase.py']
2015-10-26 21:29:59,337-test.py:63-testLog-执行dirFileOne
2015-10-26 21:29:59,339-test.py:76-testLog-ui测试dirFileOne失败
2015-10-26 21:29:59,339-test.py:63-testLog-执行testBase
2015-10-26 21:29:59,340-test.py:76-testLog-ui测试testBase失败
2015-10-26 21:29:59,506-testLogic.py:43-testLog-今天的测试任务出现了bug
2015-10-26 21:29:59,507-testLogic.py:44-testLog-Traceback (most recent call last):
  File "testLogic.py", line 41, in run
    runTest()
  File "testLogic.py", line 12, in runTest
    oneTest.sendMail()
  File "/Users/xiyuanbupt/PycharmProjects/yunZhaoBiao/manage/test.py", line 108, in sendMail
    a=self.__getEmaiTab(self.dictEmailInfo[key])
  File "/Users/xiyuanbupt/PycharmProjects/yunZhaoBiao/manage/test.py", line 103, in __getEmaiTab
    return tablib.Dataset(*data,headers=headers)
  File "/Library/Python/2.7/site-packages/tablib/core.py", line 167, in __init__
    self.headers = kwargs['headers']
  File "/Library/Python/2.7/site-packages/tablib/core.py", line 332, in _set_headers
    self._validate(collection)
  File "/Library/Python/2.7/site-packages/tablib/core.py", line 280, in _validate
    raise InvalidDimensions
InvalidDimensions

2015-10-26 21:31:42,488-test.py:25-testLog- 
2015-10-26 21:31:42,488-test.py:26-testLog-本次执行测试 ['dirFileOne.py', 'testBase.py']
2015-10-26 21:31:42,488-test.py:63-testLog-执行dirFileOne
2015-10-26 21:31:42,489-test.py:76-testLog-ui测试dirFileOne失败
2015-10-26 21:31:42,489-test.py:63-testLog-执行testBase
2015-10-26 21:31:42,490-test.py:76-testLog-ui测试testBase失败
2015-10-26 21:31:42,605-testLogic.py:43-testLog-今天的测试任务出现了bug
2015-10-26 21:31:42,606-testLogic.py:44-testLog-Traceback (most recent call last):
  File "testLogic.py", line 41, in run
    runTest()
  File "testLogic.py", line 12, in runTest
    oneTest.sendMail()
  File "/Users/xiyuanbupt/PycharmProjects/yunZhaoBiao/manage/test.py", line 110, in sendMail
    a=self.__getEmaiTab(self.dictEmailInfo[key])
  File "/Users/xiyuanbupt/PycharmProjects/yunZhaoBiao/manage/test.py", line 105, in __getEmaiTab
    return tablib.Dataset(*data,headers=headers)
  File "/Library/Python/2.7/site-packages/tablib/core.py", line 167, in __init__
    self.headers = kwargs['headers']
  File "/Library/Python/2.7/site-packages/tablib/core.py", line 332, in _set_headers
    self._validate(collection)
  File "/Library/Python/2.7/site-packages/tablib/core.py", line 280, in _validate
    raise InvalidDimensions
InvalidDimensions

2015-10-26 21:32:37,817-test.py:25-testLog- 
2015-10-26 21:32:37,817-test.py:26-testLog-本次执行测试 ['dirFileOne.py', 'testBase.py']
2015-10-26 21:32:37,817-test.py:63-testLog-执行dirFileOne
2015-10-26 21:32:37,818-test.py:76-testLog-ui测试dirFileOne失败
2015-10-26 21:32:37,818-test.py:63-testLog-执行testBase
2015-10-26 21:32:37,819-test.py:76-testLog-ui测试testBase失败
2015-10-26 21:32:37,935-testLogic.py:43-testLog-今天的测试任务出现了bug
2015-10-26 21:32:37,936-testLogic.py:44-testLog-Traceback (most recent call last):
  File "testLogic.py", line 41, in run
    runTest()
  File "testLogic.py", line 12, in runTest
    oneTest.sendMail()
  File "/Users/xiyuanbupt/PycharmProjects/yunZhaoBiao/manage/test.py", line 110, in sendMail
    a=self.__getEmaiTab(self.dictEmailInfo[key])
  File "/Users/xiyuanbupt/PycharmProjects/yunZhaoBiao/manage/test.py", line 105, in __getEmaiTab
    return tablib.Dataset(*data,headers=headers)
  File "/Library/Python/2.7/site-packages/tablib/core.py", line 167, in __init__
    self.headers = kwargs['headers']
  File "/Library/Python/2.7/site-packages/tablib/core.py", line 332, in _set_headers
    self._validate(collection)
  File "/Library/Python/2.7/site-packages/tablib/core.py", line 280, in _validate
    raise InvalidDimensions
InvalidDimensions

2015-10-26 21:34:51,745-test.py:25-testLog- 
2015-10-26 21:34:51,745-test.py:26-testLog-本次执行测试 ['dirFileOne.py', 'testBase.py']
2015-10-26 21:34:51,746-test.py:63-testLog-执行dirFileOne
2015-10-26 21:34:51,746-test.py:76-testLog-ui测试dirFileOne失败
2015-10-26 21:34:51,746-test.py:63-testLog-执行testBase
2015-10-26 21:34:51,747-test.py:76-testLog-ui测试testBase失败
2015-10-26 21:34:51,871-testLogic.py:43-testLog-今天的测试任务出现了bug
2015-10-26 21:34:51,871-testLogic.py:44-testLog-Traceback (most recent call last):
  File "testLogic.py", line 41, in run
    runTest()
  File "testLogic.py", line 12, in runTest
    oneTest.sendMail()
  File "/Users/xiyuanbupt/PycharmProjects/yunZhaoBiao/manage/test.py", line 114, in sendMail
    a=self.__getEmaiTab(self.dictEmailInfo[key])
  File "/Users/xiyuanbupt/PycharmProjects/yunZhaoBiao/manage/test.py", line 109, in __getEmaiTab
    return tablib.Dataset(*data,headers=headers)
  File "/Library/Python/2.7/site-packages/tablib/core.py", line 167, in __init__
    self.headers = kwargs['headers']
  File "/Library/Python/2.7/site-packages/tablib/core.py", line 332, in _set_headers
    self._validate(collection)
  File "/Library/Python/2.7/site-packages/tablib/core.py", line 280, in _validate
    raise InvalidDimensions
InvalidDimensions

2015-10-26 21:35:42,018-test.py:25-testLog- 
2015-10-26 21:35:42,018-test.py:26-testLog-本次执行测试 ['dirFileOne.py', 'testBase.py']
2015-10-26 21:35:42,018-test.py:63-testLog-执行dirFileOne
2015-10-26 21:35:42,019-test.py:76-testLog-ui测试dirFileOne失败
2015-10-26 21:35:42,019-test.py:63-testLog-执行testBase
2015-10-26 21:35:42,020-test.py:76-testLog-ui测试testBase失败
2015-10-26 21:43:55,339-test.py:25-testLog- 
2015-10-26 21:43:55,339-test.py:26-testLog-本次执行测试 ['dirFileOne.py', 'testBase.py']
2015-10-26 21:43:55,340-test.py:63-testLog-执行dirFileOne
2015-10-26 21:43:55,340-test.py:76-testLog-ui测试dirFileOne失败
2015-10-26 21:43:55,341-test.py:63-testLog-执行testBase
2015-10-26 21:43:55,341-test.py:76-testLog-ui测试testBase失败
2015-10-26 21:43:55,455-testLogic.py:43-testLog-今天的测试任务出现了bug
2015-10-26 21:43:55,455-testLogic.py:44-testLog-Traceback (most recent call last):
  File "testLogic.py", line 41, in run
    runTest()
  File "testLogic.py", line 12, in runTest
    oneTest.sendMail()
  File "/Users/xiyuanbupt/PycharmProjects/yunZhaoBiao/manage/test.py", line 126, in sendMail
    a=self.__getEmaiTab(self.dictEmailInfo[key])
  File "/Users/xiyuanbupt/PycharmProjects/yunZhaoBiao/manage/test.py", line 121, in __getEmaiTab
    return tablib.Dataset(*data,headers=headers)
  File "/Library/Python/2.7/site-packages/tablib/core.py", line 167, in __init__
    self.headers = kwargs['headers']
  File "/Library/Python/2.7/site-packages/tablib/core.py", line 332, in _set_headers
    self._validate(collection)
  File "/Library/Python/2.7/site-packages/tablib/core.py", line 280, in _validate
    raise InvalidDimensions
InvalidDimensions

2015-10-26 21:44:33,155-test.py:25-testLog- 
2015-10-26 21:44:33,156-test.py:26-testLog-本次执行测试 ['dirFileOne.py', 'testBase.py']
2015-10-26 21:44:33,156-test.py:63-testLog-执行dirFileOne
2015-10-26 21:44:33,157-test.py:76-testLog-ui测试dirFileOne失败
2015-10-26 21:44:33,157-test.py:63-testLog-执行testBase
2015-10-26 21:44:33,157-test.py:76-testLog-ui测试testBase失败
2015-10-26 21:44:33,278-testLogic.py:43-testLog-今天的测试任务出现了bug
2015-10-26 21:44:33,278-testLogic.py:44-testLog-Traceback (most recent call last):
  File "testLogic.py", line 41, in run
    runTest()
  File "testLogic.py", line 12, in runTest
    oneTest.sendMail()
  File "/Users/xiyuanbupt/PycharmProjects/yunZhaoBiao/manage/test.py", line 126, in sendMail
    a=self.__getEmaiTab(self.dictEmailInfo[key])
  File "/Users/xiyuanbupt/PycharmProjects/yunZhaoBiao/manage/test.py", line 121, in __getEmaiTab
    return tablib.Dataset(*data,headers=headers)
  File "/Library/Python/2.7/site-packages/tablib/core.py", line 167, in __init__
    self.headers = kwargs['headers']
  File "/Library/Python/2.7/site-packages/tablib/core.py", line 332, in _set_headers
    self._validate(collection)
  File "/Library/Python/2.7/site-packages/tablib/core.py", line 280, in _validate
    raise InvalidDimensions
InvalidDimensions

2015-10-26 21:45:32,106-test.py:25-testLog- 
2015-10-26 21:45:32,106-test.py:26-testLog-本次执行测试 ['dirFileOne.py', 'testBase.py']
2015-10-26 21:45:32,106-test.py:63-testLog-执行dirFileOne
2015-10-26 21:45:32,107-test.py:76-testLog-ui测试dirFileOne失败
2015-10-26 21:45:32,107-test.py:63-testLog-执行testBase
2015-10-26 21:45:32,108-test.py:76-testLog-ui测试testBase失败
2015-10-26 21:46:51,515-test.py:25-testLog- 
2015-10-26 21:46:51,516-test.py:26-testLog-本次执行测试 ['dirFileOne.py', 'testBase.py']
2015-10-26 21:46:51,516-test.py:63-testLog-执行dirFileOne
2015-10-26 21:46:51,517-test.py:76-testLog-ui测试dirFileOne失败
2015-10-26 21:46:51,517-test.py:63-testLog-执行testBase
2015-10-26 21:46:51,517-test.py:76-testLog-ui测试testBase失败
2015-10-26 21:46:51,637-testLogic.py:43-testLog-今天的测试任务出现了bug
2015-10-26 21:46:51,638-testLogic.py:44-testLog-Traceback (most recent call last):
  File "testLogic.py", line 41, in run
    runTest()
  File "testLogic.py", line 12, in runTest
    oneTest.sendMail()
  File "/Users/xiyuanbupt/PycharmProjects/yunZhaoBiao/manage/test.py", line 126, in sendMail
    a=self.__getEmaiTab(self.dictEmailInfo[key])
  File "/Users/xiyuanbupt/PycharmProjects/yunZhaoBiao/manage/test.py", line 121, in __getEmaiTab
    return tablib.Dataset(*data,headers=headers)
  File "/Library/Python/2.7/site-packages/tablib/core.py", line 167, in __init__
    self.headers = kwargs['headers']
  File "/Library/Python/2.7/site-packages/tablib/core.py", line 332, in _set_headers
    self._validate(collection)
  File "/Library/Python/2.7/site-packages/tablib/core.py", line 280, in _validate
    raise InvalidDimensions
InvalidDimensions

2015-10-26 21:53:19,032-test.py:25-testLog- 
2015-10-26 21:53:19,032-test.py:26-testLog-本次执行测试 ['dirFileOne.py', 'testBase.py']
2015-10-26 21:53:19,032-test.py:63-testLog-执行dirFileOne
2015-10-26 21:53:19,033-test.py:76-testLog-ui测试dirFileOne失败
2015-10-26 21:53:19,033-test.py:63-testLog-执行testBase
2015-10-26 21:53:19,034-test.py:76-testLog-ui测试testBase失败
2015-10-26 21:55:09,415-test.py:25-testLog- 
2015-10-26 21:55:09,416-test.py:26-testLog-本次执行测试 ['dirFileOne.py', 'testBase.py']
2015-10-26 21:55:09,416-test.py:63-testLog-执行dirFileOne
2015-10-26 21:55:09,417-test.py:76-testLog-ui测试dirFileOne失败
2015-10-26 21:55:09,417-test.py:63-testLog-执行testBase
2015-10-26 21:55:09,417-test.py:76-testLog-ui测试testBase失败
2015-10-26 21:55:09,534-testLogic.py:43-testLog-今天的测试任务出现了bug
2015-10-26 21:55:09,534-testLogic.py:44-testLog-Traceback (most recent call last):
  File "testLogic.py", line 41, in run
    runTest()
  File "testLogic.py", line 12, in runTest
    oneTest.sendMail()
  File "/Users/xiyuanbupt/PycharmProjects/yunZhaoBiao/manage/test.py", line 125, in sendMail
    a=self.__getEmaiTab(self.dictEmailInfo[key])
  File "/Users/xiyuanbupt/PycharmProjects/yunZhaoBiao/manage/test.py", line 119, in __getEmaiTab
    verifyData(data)
TypeError: verifyData() takes exactly 2 arguments (1 given)

2015-10-26 21:55:24,348-test.py:25-testLog- 
2015-10-26 21:55:24,349-test.py:26-testLog-本次执行测试 ['dirFileOne.py', 'testBase.py']
2015-10-26 21:55:24,349-test.py:63-testLog-执行dirFileOne
2015-10-26 21:55:24,350-test.py:76-testLog-ui测试dirFileOne失败
2015-10-26 21:55:24,350-test.py:63-testLog-执行testBase
2015-10-26 21:55:24,350-test.py:76-testLog-ui测试testBase失败
2015-10-26 22:51:35,380-test.py:25-testLog- 
2015-10-26 22:51:35,380-test.py:26-testLog-本次执行测试 ['dirFileOne.py', 'testBase.py']
2015-10-26 22:51:35,381-test.py:63-testLog-执行dirFileOne
2015-10-26 22:51:35,383-testLogic.py:44-testLog-今天的测试任务出现了bug
2015-10-26 22:51:35,383-testLogic.py:45-testLog-Traceback (most recent call last):
  File "testLogic.py", line 42, in run
    runTest()
  File "testLogic.py", line 11, in runTest
    oneTest.runTest()
  File "/Users/xiyuanbupt/PycharmProjects/yunZhaoBiao/manage/test.py", line 73, in runTest
    if tmp['res']==0:
KeyError: 'res'

2015-10-26 22:52:59,779-test.py:25-testLog- 
2015-10-26 22:52:59,779-test.py:26-testLog-本次执行测试 ['dirFileOne.py', 'testBase.py']
2015-10-26 22:52:59,779-test.py:63-testLog-执行dirFileOne
2015-10-26 22:52:59,780-testLogic.py:44-testLog-今天的测试任务出现了bug
2015-10-26 22:52:59,780-testLogic.py:45-testLog-Traceback (most recent call last):
  File "testLogic.py", line 42, in run
    runTest()
  File "testLogic.py", line 11, in runTest
    oneTest.runTest()
  File "/Users/xiyuanbupt/PycharmProjects/yunZhaoBiao/manage/test.py", line 74, in runTest
    if tmp['res']==0:
KeyError: 'res'

2015-10-26 22:53:36,588-test.py:25-testLog- 
2015-10-26 22:53:36,588-test.py:26-testLog-本次执行测试 ['dirFileOne.py', 'testBase.py']
2015-10-26 22:53:36,589-test.py:63-testLog-执行dirFileOne
2015-10-26 22:53:36,589-testLogic.py:44-testLog-今天的测试任务出现了bug
2015-10-26 22:54:10,397-test.py:25-testLog- 
2015-10-26 22:54:10,397-test.py:26-testLog-本次执行测试 ['dirFileOne.py', 'testBase.py']
2015-10-26 22:54:10,397-test.py:63-testLog-执行dirFileOne
2015-10-26 22:54:10,399-test.py:77-testLog-ui测试dirFileOne失败
2015-10-26 22:54:10,399-test.py:63-testLog-执行testBase
2015-10-26 22:54:10,400-test.py:77-testLog-ui测试testBase失败
2015-10-26 22:54:15,045-testLogic.py:44-testLog-今天的测试任务出现了bug
2015-10-26 22:54:15,045-testLogic.py:45-testLog-Traceback (most recent call last):
  File "testLogic.py", line 42, in run
    runTest()
  File "testLogic.py", line 13, in runTest
    oneTest.plot()
  File "/Users/xiyuanbupt/PycharmProjects/yunZhaoBiao/manage/test.py", line 140, in plot
    ax=fig.scatter(x_values,y_values)
AttributeError: 'Figure' object has no attribute 'scatter'

2015-10-26 22:55:01,512-test.py:25-testLog- 
2015-10-26 22:55:01,512-test.py:26-testLog-本次执行测试 ['dirFileOne.py', 'testBase.py']
2015-10-26 22:55:01,513-test.py:63-testLog-执行dirFileOne
2015-10-26 22:55:01,513-test.py:77-testLog-ui测试dirFileOne失败
2015-10-26 22:55:01,514-test.py:63-testLog-执行testBase
2015-10-26 22:55:01,514-test.py:77-testLog-ui测试testBase失败
2015-10-26 22:55:05,529-testLogic.py:44-testLog-今天的测试任务出现了bug
2015-10-26 22:55:05,529-testLogic.py:45-testLog-Traceback (most recent call last):
  File "testLogic.py", line 42, in run
    runTest()
  File "testLogic.py", line 13, in runTest
    oneTest.plot()
  File "/Users/xiyuanbupt/PycharmProjects/yunZhaoBiao/manage/test.py", line 140, in plot
    ax=fig.scatter(x_values,y_values)
AttributeError: 'Figure' object has no attribute 'scatter'

2015-10-26 22:55:39,069-test.py:25-testLog- 
2015-10-26 22:55:39,069-test.py:26-testLog-本次执行测试 ['dirFileOne.py', 'testBase.py']
2015-10-26 22:55:39,069-test.py:63-testLog-执行dirFileOne
2015-10-26 22:55:39,070-test.py:77-testLog-ui测试dirFileOne失败
2015-10-26 22:55:39,070-test.py:63-testLog-执行testBase
2015-10-26 22:55:39,071-test.py:77-testLog-ui测试testBase失败
2015-10-29 10:27:01,283-test.py:29-testLog- 
2015-10-29 10:27:01,284-test.py:30-testLog-本次执行测试 ['dirFileOne.py', 'LoginPage.py', 'process.py', 'processOne.py', 'testBase.py']
2015-10-29 10:27:01,284-test.py:67-testLog-执行dirFileOne
2015-10-29 10:27:01,286-test.py:81-testLog-ui测试dirFileOne失败
2015-10-29 10:27:01,286-test.py:67-testLog-执行processOne
2015-10-29 10:27:01,287-testLogic.py:44-testLog-今天的测试任务出现了bug
2015-10-29 10:27:01,288-testLogic.py:45-testLog-Traceback (most recent call last):
  File "testLogic.py", line 42, in run
    runTest()
  File "testLogic.py", line 11, in runTest
    oneTest.runTest()
  File "/Users/xiyuanbupt/PycharmProjects/yunZhaoBiao/manage/test.py", line 69, in runTest
    mod_all=imp.load_module(i,a[0],a[1],a[2])
  File "/Users/xiyuanbupt/PycharmProjects/yunZhaoBiao/dirTest/processOne.py", line 25
    TestBase.__init__(backEndDeveloper=backEndDeveloper,backEndLang=backEndLang,frontEndDeveloper=frontEndDeveloper,frontEndDeveloper=frontEndDeveloper,
SyntaxError: keyword argument repeated

2015-10-29 10:29:46,084-test.py:30-testLog- 
2015-10-29 10:29:46,085-test.py:31-testLog-本次执行测试 ['dirFileOne.py', 'LoginPage.py', 'process.py', 'processOne.py', 'testBase.py']
2015-10-29 10:29:46,085-test.py:68-testLog-执行dirFileOne
2015-10-29 10:29:46,085-test.py:82-testLog-ui测试dirFileOne失败
2015-10-29 10:29:46,086-test.py:68-testLog-执行processOne
2015-10-29 10:29:46,087-testLogic.py:44-testLog-今天的测试任务出现了bug
2015-10-29 10:29:46,088-testLogic.py:45-testLog-Traceback (most recent call last):
  File "testLogic.py", line 42, in run
    runTest()
  File "testLogic.py", line 11, in runTest
    oneTest.runTest()
  File "/Users/xiyuanbupt/PycharmProjects/yunZhaoBiao/manage/test.py", line 70, in runTest
    mod_all=imp.load_module(i,a[0],a[1],a[2])
  File "/Users/xiyuanbupt/PycharmProjects/yunZhaoBiao/dirTest/processOne.py", line 24
    TestBase.__init__(backEndDeveloper=backEndDeveloper,backEndLang=backEndLang,frontEndDeveloper=frontEndDeveloper,frontEndDeveloper=frontEndDeveloper,
SyntaxError: keyword argument repeated

2015-10-29 10:31:36,707-test.py:30-testLog- 
2015-10-29 10:31:36,707-test.py:31-testLog-本次执行测试 ['dirFileOne.py', 'LoginPage.py', 'process.py', 'processOne.py', 'testBase.py']
2015-10-29 10:31:36,708-test.py:68-testLog-执行dirFileOne
2015-10-29 10:31:36,708-test.py:82-testLog-ui测试dirFileOne失败
2015-10-29 10:31:36,709-test.py:68-testLog-执行processOne
2015-10-29 10:31:36,739-testLogic.py:44-testLog-今天的测试任务出现了bug
2015-10-29 10:31:36,739-testLogic.py:45-testLog-Traceback (most recent call last):
  File "testLogic.py", line 42, in run
    runTest()
  File "testLogic.py", line 11, in runTest
    oneTest.runTest()
  File "/Users/xiyuanbupt/PycharmProjects/yunZhaoBiao/manage/test.py", line 70, in runTest
    mod_all=imp.load_module(i,a[0],a[1],a[2])
  File "/Users/xiyuanbupt/PycharmProjects/yunZhaoBiao/dirTest/processOne.py", line 121, in <module>
    uiTest=ProcessOne()
TypeError: __init__() takes at least 3 arguments (1 given)

2015-10-29 10:33:30,814-test.py:30-testLog- 
2015-10-29 10:33:30,815-test.py:31-testLog-本次执行测试 ['dirFileOne.py', 'LoginPage.py', 'process.py', 'processOne.py', 'testBase.py']
2015-10-29 10:33:30,815-test.py:68-testLog-执行dirFileOne
2015-10-29 10:33:30,816-test.py:82-testLog-ui测试dirFileOne失败
2015-10-29 10:33:30,816-test.py:68-testLog-执行processOne
2015-10-29 10:33:33,004-testLogic.py:44-testLog-今天的测试任务出现了bug
2015-10-29 10:33:33,004-testLogic.py:45-testLog-Traceback (most recent call last):
  File "testLogic.py", line 42, in run
    runTest()
  File "testLogic.py", line 11, in runTest
    oneTest.runTest()
  File "/Users/xiyuanbupt/PycharmProjects/yunZhaoBiao/manage/test.py", line 70, in runTest
    mod_all=imp.load_module(i,a[0],a[1],a[2])
  File "/Users/xiyuanbupt/PycharmProjects/yunZhaoBiao/dirTest/processOne.py", line 127, in <module>
    uiTest=ProcessOne(driver,62)
  File "/Users/xiyuanbupt/PycharmProjects/yunZhaoBiao/dirTest/processOne.py", line 25, in __init__
    frontEndLan=frontEndLan,uiTester=uiTester,description=description)
TypeError: unbound method __init__() must be called with TestBase instance as first argument (got nothing instead)

2015-10-29 11:00:52,234-test.py:30-testLog- 
2015-10-29 11:00:52,235-test.py:31-testLog-本次执行测试 ['dirFileOne.py', 'LoginPage.py', 'process.py', 'processOne.py', 'testBase.py']
2015-10-29 11:00:52,235-test.py:68-testLog-执行dirFileOne
2015-10-29 11:00:52,236-test.py:82-testLog-ui测试dirFileOne失败
2015-10-29 11:00:52,236-test.py:68-testLog-执行processOne
2015-10-29 11:00:52,265-testLogic.py:44-testLog-今天的测试任务出现了bug
2015-10-29 11:00:52,265-testLogic.py:45-testLog-Traceback (most recent call last):
  File "testLogic.py", line 42, in run
    runTest()
  File "testLogic.py", line 11, in runTest
    oneTest.runTest()
  File "/Users/xiyuanbupt/PycharmProjects/yunZhaoBiao/manage/test.py", line 76, in runTest
    tmp=uiTest.getRes()
  File "/Users/xiyuanbupt/PycharmProjects/yunZhaoBiao/dirTest/testBase.py", line 55, in getRes
    self._runTest()
TypeError: _runTest() takes exactly 3 arguments (1 given)

2015-10-29 11:02:17,794-test.py:30-testLog- 
2015-10-29 11:02:17,794-test.py:31-testLog-本次执行测试 ['dirFileOne.py', 'LoginPage.py', 'process.py', 'processOne.py', 'testBase.py']
2015-10-29 11:02:17,794-test.py:68-testLog-执行dirFileOne
2015-10-29 11:02:17,795-test.py:82-testLog-ui测试dirFileOne失败
2015-10-29 11:02:17,795-test.py:68-testLog-执行processOne
2015-10-29 11:02:36,627-testLogic.py:44-testLog-今天的测试任务出现了bug
2015-10-29 11:02:36,628-testLogic.py:45-testLog-Traceback (most recent call last):
  File "testLogic.py", line 42, in run
    runTest()
  File "testLogic.py", line 11, in runTest
    oneTest.runTest()
  File "/Users/xiyuanbupt/PycharmProjects/yunZhaoBiao/manage/test.py", line 76, in runTest
    tmp=uiTest.getRes()
  File "/Users/xiyuanbupt/PycharmProjects/yunZhaoBiao/dirTest/processOne.py", line 148, in getRes
    self._runTest(driver,61)
  File "/Users/xiyuanbupt/PycharmProjects/yunZhaoBiao/dirTest/processOne.py", line 119, in _runTest
    processOne=ProcessOne(driver,proId)
  File "/Users/xiyuanbupt/PycharmProjects/yunZhaoBiao/dirTest/processOne.py", line 26, in __init__
    self.success=self.completeProZero()
  File "/Users/xiyuanbupt/PycharmProjects/yunZhaoBiao/dirTest/processOne.py", line 43, in completeProZero
    tmpOptions=self.driver.find_element_by_css_selector('html.ng-scope body div.ng-scope div.wrap.ng-scope div.wrap_r div.w_r_t div.ng-scope div.wrt_xxin.ng-scope div.ng-scope div.wrt_xxin_l.ng-scope div.wrt_x_l_c div.ng-scope div.wrt_xltb1it_li select.wrtxlc_li_txt1.yh.ng-pristine.ng-valid')
  File "/Library/Python/2.7/site-packages/selenium/webdriver/remote/webdriver.py", line 397, in find_element_by_css_selector
    return self.find_element(by=By.CSS_SELECTOR, value=css_selector)
  File "/Library/Python/2.7/site-packages/selenium/webdriver/remote/webdriver.py", line 707, in find_element
    {'using': by, 'value': value})['value']
  File "/Library/Python/2.7/site-packages/selenium/webdriver/remote/webdriver.py", line 196, in execute
    self.error_handler.check_response(response)
  File "/Library/Python/2.7/site-packages/selenium/webdriver/remote/errorhandler.py", line 181, in check_response
    raise exception_class(message, screen, stacktrace)
NoSuchElementException: Message: Unable to locate element: {"method":"css selector","selector":"html.ng-scope body div.ng-scope div.wrap.ng-scope div.wrap_r div.w_r_t div.ng-scope div.wrt_xxin.ng-scope div.ng-scope div.wrt_xxin_l.ng-scope div.wrt_x_l_c div.ng-scope div.wrt_xltb1it_li select.wrtxlc_li_txt1.yh.ng-pristine.ng-valid"}
Stacktrace:
    at FirefoxDriver.prototype.findElementInternal_ (file:///var/folders/p7/0wgl9v7s63q112sl16dkyc9c0000gn/T/tmpYEvduW/extensions/fxdriver@googlecode.com/components/driver-component.js:10667)
    at fxdriver.Timer.prototype.setTimeout/<.notify (file:///var/folders/p7/0wgl9v7s63q112sl16dkyc9c0000gn/T/tmpYEvduW/extensions/fxdriver@googlecode.com/components/driver-component.js:623)

2015-10-29 11:06:16,514-test.py:30-testLog- 
2015-10-29 11:06:16,514-test.py:31-testLog-本次执行测试 ['dirFileOne.py', 'LoginPage.py', 'process.py', 'processOne.py', 'testBase.py']
2015-10-29 11:06:16,514-test.py:68-testLog-执行dirFileOne
2015-10-29 11:06:16,515-test.py:82-testLog-ui测试dirFileOne失败
2015-10-29 11:06:16,515-test.py:68-testLog-执行processOne
2015-10-29 11:06:36,176-test.py:82-testLog-ui测试processOne失败
2015-10-29 11:06:36,176-test.py:68-testLog-执行testBase
2015-10-29 11:06:36,177-test.py:82-testLog-ui测试testBase失败
2015-10-29 11:08:21,962-test.py:30-testLog- 
2015-10-29 11:08:21,962-test.py:31-testLog-本次执行测试 ['dirFileOne.py', 'LoginPage.py', 'process.py', 'processOne.py', 'testBase.py']
2015-10-29 11:08:21,962-test.py:68-testLog-执行dirFileOne
2015-10-29 11:08:21,964-test.py:85-testLog-ui测试dirFileOne成功
2015-10-29 11:08:21,964-test.py:68-testLog-执行processOne
2015-10-29 11:09:16,772-test.py:85-testLog-ui测试processOne成功
2015-10-29 11:09:16,772-test.py:68-testLog-执行testBase
2015-10-29 11:09:16,772-test.py:85-testLog-ui测试testBase成功
2015-10-29 11:10:55,587-test.py:30-testLog- 
2015-10-29 11:10:55,587-test.py:31-testLog-本次执行测试 ['dirFileOne.py', 'LoginPage.py', 'process.py', 'processOne.py', 'testBase.py']
2015-10-29 11:10:55,588-test.py:68-testLog-执行dirFileOne
2015-10-29 11:10:55,588-test.py:85-testLog-ui测试dirFileOne成功
2015-10-29 11:10:55,589-test.py:68-testLog-执行processOne
2015-10-29 11:11:53,037-testLogic.py:44-testLog-今天的测试任务出现了bug
2015-10-29 11:11:53,040-testLogic.py:45-testLog-Traceback (most recent call last):
  File "testLogic.py", line 42, in run
    runTest()
  File "testLogic.py", line 11, in runTest
    oneTest.runTest()
  File "/Users/xiyuanbupt/PycharmProjects/yunZhaoBiao/manage/test.py", line 76, in runTest
    tmp=uiTest.getRes()
  File "/Users/xiyuanbupt/PycharmProjects/yunZhaoBiao/dirTest/processOne.py", line 165, in getRes
    driver.close()
  File "/Library/Python/2.7/site-packages/selenium/webdriver/remote/webdriver.py", line 468, in close
    self.execute(Command.CLOSE)
  File "/Library/Python/2.7/site-packages/selenium/webdriver/remote/webdriver.py", line 194, in execute
    response = self.command_executor.execute(driver_command, params)
  File "/Library/Python/2.7/site-packages/selenium/webdriver/remote/remote_connection.py", line 395, in execute
    return self._request(command_info[0], url, body=data)
  File "/Library/Python/2.7/site-packages/selenium/webdriver/remote/remote_connection.py", line 425, in _request
    self._conn.request(method, parsed_url.path, body, headers)
  File "/System/Library/Frameworks/Python.framework/Versions/2.7/lib/python2.7/httplib.py", line 1053, in request
    self._send_request(method, url, body, headers)
  File "/System/Library/Frameworks/Python.framework/Versions/2.7/lib/python2.7/httplib.py", line 1093, in _send_request
    self.endheaders(body)
  File "/System/Library/Frameworks/Python.framework/Versions/2.7/lib/python2.7/httplib.py", line 1049, in endheaders
    self._send_output(message_body)
  File "/System/Library/Frameworks/Python.framework/Versions/2.7/lib/python2.7/httplib.py", line 893, in _send_output
    self.send(msg)
  File "/System/Library/Frameworks/Python.framework/Versions/2.7/lib/python2.7/httplib.py", line 855, in send
    self.connect()
  File "/System/Library/Frameworks/Python.framework/Versions/2.7/lib/python2.7/httplib.py", line 832, in connect
    self.timeout, self.source_address)
  File "/System/Library/Frameworks/Python.framework/Versions/2.7/lib/python2.7/socket.py", line 575, in create_connection
    raise err
error: [Errno 61] Connection refused

2015-10-29 11:12:10,504-test.py:30-testLog- 
2015-10-29 11:12:10,504-test.py:31-testLog-本次执行测试 ['dirFileOne.py', 'LoginPage.py', 'process.py', 'processOne.py', 'testBase.py']
2015-10-29 11:12:10,504-test.py:68-testLog-执行dirFileOne
2015-10-29 11:12:10,505-test.py:85-testLog-ui测试dirFileOne成功
2015-10-29 11:12:10,506-test.py:68-testLog-执行processOne
2015-10-29 11:12:32,661-testLogic.py:44-testLog-今天的测试任务出现了bug
2015-10-29 11:12:32,663-testLogic.py:45-testLog-Traceback (most recent call last):
  File "testLogic.py", line 42, in run
    runTest()
  File "testLogic.py", line 11, in runTest
    oneTest.runTest()
  File "/Users/xiyuanbupt/PycharmProjects/yunZhaoBiao/manage/test.py", line 76, in runTest
    tmp=uiTest.getRes()
  File "/Users/xiyuanbupt/PycharmProjects/yunZhaoBiao/dirTest/processOne.py", line 165, in getRes
    driver.close()
  File "/Library/Python/2.7/site-packages/selenium/webdriver/remote/webdriver.py", line 468, in close
    self.execute(Command.CLOSE)
  File "/Library/Python/2.7/site-packages/selenium/webdriver/remote/webdriver.py", line 194, in execute
    response = self.command_executor.execute(driver_command, params)
  File "/Library/Python/2.7/site-packages/selenium/webdriver/remote/remote_connection.py", line 395, in execute
    return self._request(command_info[0], url, body=data)
  File "/Library/Python/2.7/site-packages/selenium/webdriver/remote/remote_connection.py", line 425, in _request
    self._conn.request(method, parsed_url.path, body, headers)
  File "/System/Library/Frameworks/Python.framework/Versions/2.7/lib/python2.7/httplib.py", line 1053, in request
    self._send_request(method, url, body, headers)
  File "/System/Library/Frameworks/Python.framework/Versions/2.7/lib/python2.7/httplib.py", line 1087, in _send_request
    self.putrequest(method, url, **skips)
  File "/System/Library/Frameworks/Python.framework/Versions/2.7/lib/python2.7/httplib.py", line 935, in putrequest
    raise CannotSendRequest()
CannotSendRequest

2015-10-29 11:14:49,734-test.py:30-testLog- 
2015-10-29 11:14:49,735-test.py:31-testLog-本次执行测试 ['dirFileOne.py', 'LoginPage.py', 'process.py', 'processOne.py', 'testBase.py']
2015-10-29 11:14:49,735-test.py:68-testLog-执行dirFileOne
2015-10-29 11:14:49,736-test.py:85-testLog-ui测试dirFileOne成功
2015-10-29 11:14:49,736-test.py:68-testLog-执行processOne
2015-10-29 11:15:09,405-test.py:82-testLog-ui测试processOne失败
2015-10-29 11:15:09,405-test.py:68-testLog-执行testBase
2015-10-29 11:15:09,405-test.py:85-testLog-ui测试testBase成功
2015-10-29 11:21:35,622-test.py:30-testLog- 
2015-10-29 11:21:35,622-test.py:31-testLog-本次执行测试 ['dirFileOne.py', 'LoginPage.py', 'process.py', 'processOne.py', 'testBase.py']
2015-10-29 11:21:35,623-test.py:68-testLog-执行dirFileOne
2015-10-29 11:21:35,623-test.py:85-testLog-ui测试dirFileOne成功
2015-10-29 11:21:35,623-test.py:68-testLog-执行processOne
2015-10-29 11:21:53,927-testLogic.py:44-testLog-今天的测试任务出现了bug
2015-10-29 11:21:53,927-testLogic.py:45-testLog-Traceback (most recent call last):
  File "testLogic.py", line 42, in run
    runTest()
  File "testLogic.py", line 11, in runTest
    oneTest.runTest()
  File "/Users/xiyuanbupt/PycharmProjects/yunZhaoBiao/manage/test.py", line 76, in runTest
    tmp=uiTest.getRes()
  File "/Users/xiyuanbupt/PycharmProjects/yunZhaoBiao/dirTest/processOne.py", line 161, in getRes
    res['detail']=self.res['detail']
KeyError: 'detail'

2015-10-29 11:22:45,699-test.py:30-testLog- 
2015-10-29 11:22:45,699-test.py:31-testLog-本次执行测试 ['dirFileOne.py', 'LoginPage.py', 'process.py', 'processOne.py', 'testBase.py']
2015-10-29 11:22:45,699-test.py:68-testLog-执行dirFileOne
2015-10-29 11:22:45,700-test.py:85-testLog-ui测试dirFileOne成功
2015-10-29 11:22:45,700-test.py:68-testLog-执行processOne
2015-10-29 11:23:03,879-testLogic.py:44-testLog-今天的测试任务出现了bug
2015-10-29 11:23:03,880-testLogic.py:45-testLog-Traceback (most recent call last):
  File "testLogic.py", line 42, in run
    runTest()
  File "testLogic.py", line 11, in runTest
    oneTest.runTest()
  File "/Users/xiyuanbupt/PycharmProjects/yunZhaoBiao/manage/test.py", line 76, in runTest
    tmp=uiTest.getRes()
  File "/Users/xiyuanbupt/PycharmProjects/yunZhaoBiao/dirTest/processOne.py", line 161, in getRes
    res['detail']=self.res['detail']
KeyError: 'detail'

2015-10-29 11:23:45,030-test.py:30-testLog- 
2015-10-29 11:23:45,030-test.py:31-testLog-本次执行测试 ['dirFileOne.py', 'LoginPage.py', 'process.py', 'processOne.py', 'testBase.py']
2015-10-29 11:23:45,030-test.py:68-testLog-执行dirFileOne
2015-10-29 11:23:45,031-test.py:85-testLog-ui测试dirFileOne成功
2015-10-29 11:23:45,031-test.py:68-testLog-执行processOne
2015-10-29 11:24:16,309-test.py:85-testLog-ui测试processOne成功
2015-10-29 11:24:16,309-test.py:68-testLog-执行testBase
2015-10-29 11:24:16,310-test.py:85-testLog-ui测试testBase成功
2015-10-29 11:27:31,735-test.py:30-testLog- 
2015-10-29 11:27:31,735-test.py:31-testLog-本次执行测试 ['dirFileOne.py', 'LoginPage.py', 'process.py', 'processOne.py', 'testBase.py']
2015-10-29 11:27:31,735-test.py:68-testLog-执行dirFileOne
2015-10-29 11:27:31,736-test.py:85-testLog-ui测试dirFileOne成功
2015-10-29 11:27:31,736-test.py:68-testLog-执行processOne
2015-10-29 11:27:50,121-testLogic.py:44-testLog-今天的测试任务出现了bug
2015-10-29 11:27:50,122-testLogic.py:45-testLog-Traceback (most recent call last):
  File "testLogic.py", line 42, in run
    runTest()
  File "testLogic.py", line 11, in runTest
    oneTest.runTest()
  File "/Users/xiyuanbupt/PycharmProjects/yunZhaoBiao/manage/test.py", line 81, in runTest
    self.__addEmailInfo(tmp,'%s.py'%(i))
  File "/Users/xiyuanbupt/PycharmProjects/yunZhaoBiao/manage/test.py", line 47, in __addEmailInfo
    info['detail']=res['detail']
KeyError: 'detail'

2015-10-29 11:28:48,547-test.py:30-testLog- 
2015-10-29 11:28:48,547-test.py:31-testLog-本次执行测试 ['dirFileOne.py', 'LoginPage.py', 'process.py', 'processOne.py', 'testBase.py']
2015-10-29 11:28:48,547-test.py:68-testLog-执行dirFileOne
2015-10-29 11:28:48,548-test.py:85-testLog-ui测试dirFileOne成功
2015-10-29 11:28:48,548-test.py:68-testLog-执行processOne
2015-10-29 11:29:07,073-testLogic.py:44-testLog-今天的测试任务出现了bug
2015-10-29 11:29:07,074-testLogic.py:45-testLog-Traceback (most recent call last):
  File "testLogic.py", line 42, in run
    runTest()
  File "testLogic.py", line 11, in runTest
    oneTest.runTest()
  File "/Users/xiyuanbupt/PycharmProjects/yunZhaoBiao/manage/test.py", line 81, in runTest
    self.__addEmailInfo(tmp,'%s.py'%(i))
  File "/Users/xiyuanbupt/PycharmProjects/yunZhaoBiao/manage/test.py", line 46, in __addEmailInfo
    info['failPicDir']=res['failPicDir']
KeyError: 'failPicDir'

2015-10-29 11:29:28,054-test.py:30-testLog- 
2015-10-29 11:29:28,054-test.py:31-testLog-本次执行测试 ['dirFileOne.py', 'LoginPage.py', 'process.py', 'processOne.py', 'testBase.py']
2015-10-29 11:29:28,054-test.py:68-testLog-执行dirFileOne
2015-10-29 11:29:28,055-test.py:85-testLog-ui测试dirFileOne成功
2015-10-29 11:29:28,055-test.py:68-testLog-执行processOne
2015-10-29 11:29:46,307-testLogic.py:44-testLog-今天的测试任务出现了bug
2015-10-29 11:29:46,307-testLogic.py:45-testLog-Traceback (most recent call last):
  File "testLogic.py", line 42, in run
    runTest()
  File "testLogic.py", line 11, in runTest
    oneTest.runTest()
  File "/Users/xiyuanbupt/PycharmProjects/yunZhaoBiao/manage/test.py", line 81, in runTest
    self.__addEmailInfo(tmp,'%s.py'%(i))
  File "/Users/xiyuanbupt/PycharmProjects/yunZhaoBiao/manage/test.py", line 46, in __addEmailInfo
    info['failPicDir']=res['failPicDir']
KeyError: 'failPicDir'

2015-10-29 11:31:00,811-test.py:30-testLog- 
2015-10-29 11:31:00,811-test.py:31-testLog-本次执行测试 ['dirFileOne.py', 'LoginPage.py', 'process.py', 'processOne.py', 'testBase.py']
2015-10-29 11:31:00,812-test.py:68-testLog-执行dirFileOne
2015-10-29 11:31:00,812-test.py:85-testLog-ui测试dirFileOne成功
2015-10-29 11:31:00,813-test.py:68-testLog-执行processOne
2015-10-29 11:31:22,006-testLogic.py:44-testLog-今天的测试任务出现了bug
2015-10-29 11:31:22,006-testLogic.py:45-testLog-Traceback (most recent call last):
  File "testLogic.py", line 42, in run
    runTest()
  File "testLogic.py", line 11, in runTest
    oneTest.runTest()
  File "/Users/xiyuanbupt/PycharmProjects/yunZhaoBiao/manage/test.py", line 81, in runTest
    self.__addEmailInfo(tmp,'%s.py'%(i))
  File "/Users/xiyuanbupt/PycharmProjects/yunZhaoBiao/manage/test.py", line 46, in __addEmailInfo
    info['failPicDir']=res['failPicDir']
KeyError: 'failPicDir'

2015-10-29 11:31:36,668-test.py:30-testLog- 
2015-10-29 11:31:36,668-test.py:31-testLog-本次执行测试 ['dirFileOne.py', 'LoginPage.py', 'process.py', 'processOne.py', 'testBase.py']
2015-10-29 11:31:36,668-test.py:68-testLog-执行dirFileOne
2015-10-29 11:31:36,669-test.py:85-testLog-ui测试dirFileOne成功
2015-10-29 11:31:36,669-test.py:68-testLog-执行processOne
2015-10-29 11:31:46,695-testLogic.py:44-testLog-今天的测试任务出现了bug
2015-10-29 11:31:46,697-testLogic.py:45-testLog-Traceback (most recent call last):
  File "testLogic.py", line 42, in run
    runTest()
  File "testLogic.py", line 11, in runTest
    oneTest.runTest()
  File "/Users/xiyuanbupt/PycharmProjects/yunZhaoBiao/manage/test.py", line 76, in runTest
    tmp=uiTest.getRes()
  File "/Users/xiyuanbupt/PycharmProjects/yunZhaoBiao/dirTest/processOne.py", line 153, in getRes
    driver.close()
  File "/Library/Python/2.7/site-packages/selenium/webdriver/remote/webdriver.py", line 468, in close
    self.execute(Command.CLOSE)
  File "/Library/Python/2.7/site-packages/selenium/webdriver/remote/webdriver.py", line 194, in execute
    response = self.command_executor.execute(driver_command, params)
  File "/Library/Python/2.7/site-packages/selenium/webdriver/remote/remote_connection.py", line 395, in execute
    return self._request(command_info[0], url, body=data)
  File "/Library/Python/2.7/site-packages/selenium/webdriver/remote/remote_connection.py", line 425, in _request
    self._conn.request(method, parsed_url.path, body, headers)
  File "/System/Library/Frameworks/Python.framework/Versions/2.7/lib/python2.7/httplib.py", line 1053, in request
    self._send_request(method, url, body, headers)
  File "/System/Library/Frameworks/Python.framework/Versions/2.7/lib/python2.7/httplib.py", line 1093, in _send_request
    self.endheaders(body)
  File "/System/Library/Frameworks/Python.framework/Versions/2.7/lib/python2.7/httplib.py", line 1049, in endheaders
    self._send_output(message_body)
  File "/System/Library/Frameworks/Python.framework/Versions/2.7/lib/python2.7/httplib.py", line 893, in _send_output
    self.send(msg)
  File "/System/Library/Frameworks/Python.framework/Versions/2.7/lib/python2.7/httplib.py", line 855, in send
    self.connect()
  File "/System/Library/Frameworks/Python.framework/Versions/2.7/lib/python2.7/httplib.py", line 832, in connect
    self.timeout, self.source_address)
  File "/System/Library/Frameworks/Python.framework/Versions/2.7/lib/python2.7/socket.py", line 575, in create_connection
    raise err
error: [Errno 61] Connection refused

2015-10-29 11:32:46,925-test.py:30-testLog- 
2015-10-29 11:32:46,925-test.py:31-testLog-本次执行测试 ['dirFileOne.py', 'LoginPage.py', 'process.py', 'processOne.py', 'testBase.py']
2015-10-29 11:32:46,925-test.py:68-testLog-执行dirFileOne
2015-10-29 11:32:46,926-test.py:85-testLog-ui测试dirFileOne成功
2015-10-29 11:32:46,926-test.py:68-testLog-执行processOne
2015-10-29 11:33:18,489-test.py:85-testLog-ui测试processOne成功
2015-10-29 11:33:18,489-test.py:68-testLog-执行testBase
2015-10-29 11:33:18,490-test.py:85-testLog-ui测试testBase成功
2015-10-29 11:34:46,649-test.py:30-testLog- 
2015-10-29 11:34:46,650-test.py:31-testLog-本次执行测试 ['dirFileOne.py', 'LoginPage.py', 'process.py', 'processOne.py', 'testBase.py']
2015-10-29 11:34:46,650-test.py:68-testLog-执行dirFileOne
2015-10-29 11:34:46,651-test.py:85-testLog-ui测试dirFileOne成功
2015-10-29 11:34:46,651-test.py:68-testLog-执行testBase
2015-10-29 11:34:46,652-test.py:85-testLog-ui测试testBase成功
2015-10-29 11:35:20,157-test.py:30-testLog- 
2015-10-29 11:35:20,158-test.py:31-testLog-本次执行测试 ['dirFileOne.py', 'LoginPage.py', 'process.py', 'processOne.py', 'testBase.py']
2015-10-29 11:35:20,158-test.py:68-testLog-执行dirFileOne
2015-10-29 11:35:20,160-test.py:85-testLog-ui测试dirFileOne成功
2015-10-29 11:35:20,160-test.py:68-testLog-执行testBase
2015-10-29 11:35:20,160-test.py:85-testLog-ui测试testBase成功
2015-10-29 11:36:00,052-test.py:30-testLog- 
2015-10-29 11:36:00,052-test.py:31-testLog-本次执行测试 ['dirFileOne.py', 'LoginPage.py', 'process.py', 'processOne.py', 'testBase.py']
2015-10-29 11:36:00,052-test.py:68-testLog-执行dirFileOne
2015-10-29 11:36:00,053-test.py:85-testLog-ui测试dirFileOne成功
2015-10-29 11:36:00,053-test.py:68-testLog-执行testBase
2015-10-29 11:36:00,054-test.py:85-testLog-ui测试testBase成功
2015-10-29 11:36:59,764-test.py:30-testLog- 
2015-10-29 11:36:59,764-test.py:31-testLog-本次执行测试 ['dirFileOne.py', 'LoginPage.py', 'process.py', 'processOne.py', 'testBase.py']
2015-10-29 11:36:59,764-test.py:68-testLog-执行dirFileOne
2015-10-29 11:36:59,765-test.py:85-testLog-ui测试dirFileOne成功
2015-10-29 11:36:59,766-test.py:68-testLog-执行testBase
2015-10-29 11:36:59,766-test.py:85-testLog-ui测试testBase成功
